Workbook

Sheet Run 1 Gen 1 
A1: Run 1 Gen 1
B4: Cycle | C4: Operating Hour | D4: Operating Hour Cumulative Gen 1 | E4: CO₂In during adsorption | M4: CO₂Out during adsorption | Q4: CO₂ Captured | Z4: CO₂Regen during steaming
E5: Q (Nm³/h) | F5: C (vol%) | I5: T (min) | J5: CO₂ (kg) | M5: Q (Nm³/h) | N5: C (vol%) | O5: T (min) | P5: CO₂ (kg) | Q5: CO₂ Captured Run 1 Gen 1 | T5: CO₂ Captured Run 1 Gen 1 Cumulative (Kg) | W5: % Captured | Z5: Q (Nm³/h) | AA5: C (vol%) | AB5: T (min) | AC5: CO₂ (kg) | AD5: CO2 Recovery Run 1 Gen 1 Cumulative (Kg) | AE5: % Recovery
F6: 10.1 | G6: 14.9 | H6: 17.1 | J6: 10.1 | K6: 14.9 | L6: 17.1 | Q6: 10.1 | R6: 14.9 | S6: 17.1 | T6: 10.1 | U6: 14.9 | V6: 17.1 | W6: 10.1 | X6: 14.9 | Y6: 17.1 | AE6: 10.1 | AF6: 14.9 | AG6: 17.1
A7: 45903 | B7: 1 | C7: 0.27916667 | D7: =C7 -> 0.27916667 | E7: 18.08 | F7: 10.1 | G7: 14.9 | H7: 17.1 | I7: 48 | J7: =E7*F7*1.84*(I7/60)*0.01 -> 2.6879898 | K7: =E7*G7*1.84*(I7/60)*0.01 -> 3.9654502 | L7: =E7*H7*1.84*(I7/60)*0.01 -> 4.550953 | M7: 15 | N7: 0.0005 | O7: 48 | P7: =M7*N7*1.84*(O7/60)*0.01 -> 0.0001104 | Q7: =IFERROR(J7-$P7,0) -> 2.6878794 | R7: =IFERROR(K7-$P7,0) -> 3.9653398 | S7: =IFERROR(L7-$P7,0) -> 4.5508426 | T7: =Q7 -> 2.6878794 | U7: =R7 -> 3.9653398 | V7: =S7 -> 4.5508426 | W7: =IFERROR(ROUND(Q7/J7*100,2),0) -> 100 | X7: =IFERROR(ROUND(R7/K7*100,2),0) -> 100 | Y7: =IFERROR(ROUND(S7/L7*100,2),0) -> 100 | Z7: 0.20002732 | AA7: 53.88 | AB7: 61 | AC7: =Z7*AA7*1.84*(AB7/60)*0.01 -> 0.20161058 | AD7: =AC7 -> 0.20161058 | AE7: =IFERROR(ROUND($AC7/Q7*100,2),0) -> 7.5 | AF7: =IFERROR(ROUND($AC7/R7*100,2),0) -> 5.08 | AG7: =IFERROR(ROUND($AC7/S7*100,2),0) -> 4.43
A8: 45905 | B8: 2 | C8: 0.33472222 | D8: =C8+D7 -> 0.61388889 | E8: 15.32 | F8: 10.1 | G8: 14.9 | H8: 17.1 | I8: 141 | J8: =E8*F8*1.84*(I8/60)*0.01 -> 6.6906117 | K8: =E8*G8*1.84*(I8/60)*0.01 -> 9.8703083 | L8: =E8*H8*1.84*(I8/60)*0.01 -> 11.327669 | M8: 15 | N8: 0.00015898585 | O8: 141 | P8: =M8*N8*1.84*(O8/60)*0.01 -> 0.00010311822 | Q8: =IFERROR(J8-$P8,0) -> 6.6905086 | R8: =IFERROR(K8-$P8,0) -> 9.8702052 | S8: =IFERROR(L8-$P8,0) -> 11.327566 | T8: =Q8+T7 -> 9.3783879 | U8: =R8+U7 -> 13.835545 | V8: =S8+V7 -> 15.878409 | W8: =IFERROR(ROUND(Q8/J8*100,2),0) -> 100 | X8: =IFERROR(ROUND(R8/K8*100,2),0) -> 100 | Y8: =IFERROR(ROUND(S8/L8*100,2),0) -> 100 | Z8: 0.20002732 | AA8: 53.88 | AB8: 61 | AC8: =Z8*AA8*1.84*(AB8/60)*0.01 -> 0.20161058 | AD8: =AC8+AD7 -> 0.40322116 | AE8: =IFERROR(ROUND($AC8/Q8*100,2),0) -> 3.01 | AF8: =IFERROR(ROUND($AC8/R8*100,2),0) -> 2.04 | AG8: =IFERROR(ROUND($AC8/S8*100,2),0) -> 1.78
A9: 45908 | B9: 3 | C9: 0.24722222 | D9: =C9+D8 -> 0.86111111 | E9: 16.68 | F9: 10.1 | G9: 14.9 | H9: 17.1 | I9: 92 | J9: =E9*F9*1.84*(I9/60)*0.01 -> 4.7530438 | K9: =E9*G9*1.84*(I9/60)*0.01 -> 7.0119162 | L9: =E9*H9*1.84*(I9/60)*0.01 -> 8.0472326 | M9: 15 | N9: 0.0016 | O9: 92 | P9: =M9*N9*1.84*(O9/60)*0.01 -> 0.00067712 | Q9: =IFERROR(J9-$P9,0) -> 4.7523667 | R9: =IFERROR(K9-$P9,0) -> 7.011239 | S9: =IFERROR(L9-$P9,0) -> 8.0465555 | T9: =Q9+T8 -> 14.130755 | U9: =R9+U8 -> 20.846784 | V9: =S9+V8 -> 23.924964 | W9: =IFERROR(ROUND(Q9/J9*100,2),0) -> 99.99 | X9: =IFERROR(ROUND(R9/K9*100,2),0) -> 99.99 | Y9: =IFERROR(ROUND(S9/L9*100,2),0) -> 99.99 | Z9: 0.5 | AA9: 53.88 | AB9: 58.5 | AC9: =Z9*AA9*1.84*(AB9/60)*0.01 -> 0.4833036 | AD9: =AC9+AD8 -> 0.88652476 | AE9: =IFERROR(ROUND($AC9/Q9*100,2),0) -> 10.17 | AF9: =IFERROR(ROUND($AC9/R9*100,2),0) -> 6.89 | AG9: =IFERROR(ROUND($AC9/S9*100,2),0) -> 6.01
A10: 45909 | B10: 4 | C10: 0.28055556 | D10: =C10+D9 -> 1.1416667 | E10: 16.57 | F10: 10.1 | G10: 14.9 | H10: 17.1 | I10: 107.16667 | J10: =E10*F10*1.84*(I10/60)*0.01 -> 5.5000948 | K10: =E10*G10*1.84*(I10/60)*0.01 -> 8.1140013 | L10: =E10*H10*1.84*(I10/60)*0.01 -> 9.3120417 | M10: 15 | N10: 0.00059543478 | O10: 107.16667 | P10: =M10*N10*1.84*(O10/60)*0.01 -> 0.0002935295 | Q10: =IFERROR(J10-$P10,0) -> 5.4998013 | R10: =IFERROR(K10-$P10,0) -> 8.1137078 | S10: =IFERROR(L10-$P10,0) -> 9.3117482 | T10: =Q10+T9 -> 19.630556 | U10: =R10+U9 -> 28.960492 | V10: =S10+V9 -> 33.236712 | W10: =IFERROR(ROUND(Q10/J10*100,2),0) -> 99.99 | X10: =IFERROR(ROUND(R10/K10*100,2),0) -> 100 | Y10: =IFERROR(ROUND(S10/L10*100,2),0) -> 100 | Z10: 0.45699454 | AA10: 53.88 | AB10: 61 | AC10: =ROUND(Z10*AA10*1.84*(AB10/60)*0.01,2) -> 0.46 | AD10: =AC10+AD9 -> 1.3465248 | AE10: =IFERROR(ROUND($AC10/Q10*100,2),0) -> 8.36 | AF10: =IFERROR(ROUND($AC10/R10*100,2),0) -> 5.67 | AG10: =IFERROR(ROUND($AC10/S10*100,2),0) -> 4.94
A11: 45911 | B11: 5 | C11: 0.27222222 | D11: =C11+D10 -> 1.4138889 | E11: 16.08 | F11: 10.1 | G11: 14.9 | H11: 17.1 | I11: 292 | J11: =E11*F11*1.84*(I11/60)*0.01 -> 14.543095 | K11: =E11*G11*1.84*(I11/60)*0.01 -> 21.454665 | L11: =E11*H11*1.84*(I11/60)*0.01 -> 24.622468 | M11: 5 | N11: 0.0005 | O11: 292 | P11: =M11*N11*1.84*(O11/60)*0.01 -> 0.00022386667 | Q11: =IFERROR(J11-$P11,0) -> 14.542871 | R11: =IFERROR(K11-$P11,0) -> 21.454441 | S11: =IFERROR(L11-$P11,0) -> 24.622244 | T11: =Q11+T10 -> 34.173427 | U11: =R11+U10 -> 50.414933 | V11: =S11+V10 -> 57.858956 | W11: =IFERROR(ROUND(Q11/J11*100,2),0) -> 100 | X11: =IFERROR(ROUND(R11/K11*100,2),0) -> 100 | Y11: =IFERROR(ROUND(S11/L11*100,2),0) -> 100 | Z11: - | AA11: - | AB11: - | AC11: 0 | AD11: =AC11+AD10 -> 1.3465248
A12: 45912 | B12: 6 | C12: 0.22152778 | D12: =C12+D11 -> 1.6354167 | E12: 26.75 | F12: 10.1 | G12: 14.9 | H12: 17.1 | I12: 44.833333 | J12: =E12*F12*1.84*(I12/60)*0.01 -> 3.7146061 | K12: =E12*G12*1.84*(I12/60)*0.01 -> 5.4799634 | L12: =E12*H12*1.84*(I12/60)*0.01 -> 6.2890855 | M12: 15 | N12: 4.0222222e-05 | O12: 44.833333 | P12: =M12*N12*1.84*(O12/60)*0.01 -> 8.295163e-06 | Q12: =IFERROR(J12-$P12,0) -> 3.7145978 | R12: =IFERROR(K12-$P12,0) -> 5.4799551 | S12: =IFERROR(L12-$P12,0) -> 6.2890772 | T12: =Q12+T11 -> 37.888025 | U12: =R12+U11 -> 55.894888 | V12: =S12+V11 -> 64.148034 | W12: =IFERROR(ROUND(Q12/J12*100,2),0) -> 100 | X12: =IFERROR(ROUND(R12/K12*100,2),0) -> 100 | Y12: =IFERROR(ROUND(S12/L12*100,2),0) -> 100 | Z12: 1.0832895 | AA12: 53.88 | AB12: 76 | AC12: =ROUND(Z12*AA12*1.84*(AB12/60)*0.01,2) -> 1.36 | AD12: =AC12+AD11 -> 2.7065248 | AE12: =IFERROR(ROUND($AC12/Q12*100,2),0) -> 36.61 | AF12: =IFERROR(ROUND($AC12/R12*100,2),0) -> 24.82 | AG12: =IFERROR(ROUND($AC12/S12*100,2),0) -> 21.62
A13: 45915 | B13: 7 | C13: 0.29652778 | D13: =C13+D12 -> 1.9319444 | E13: - | F13: 10.1 | G13: 14.9 | H13: 17.1 | I13: - | J13: - | K13: - | L13: - | M13: - | N13: - | O13: - | P13: - | Q13: =IFERROR(J13-$P13,0) -> 0 | R13: =IFERROR(K13-$P13,0) -> 0 | S13: =IFERROR(L13-$P13,0) -> 0 | T13: =Q13+T12 -> 37.888025 | U13: =R13+U12 -> 55.894888 | V13: =S13+V12 -> 64.148034 | Z13: 1.34 | AA13: 53.88 | AB13: 60.833333 | AC13: =ROUND(Z13*AA13*1.84*(AB13/60)*0.01,2) -> 1.35 | AD13: =AC13+AD12 -> 4.0565248
A14: 45916 | B14: 8 | C14: 0.27222222 | D14: =C14+D13 -> 2.2041667 | E14: 25.379024 | F14: 10.1 | G14: 14.9 | H14: 17.1 | I14: 68.166667 | J14: =E14*F14*1.84*(I14/60)*0.01 -> 5.3583975 | K14: =E14*G14*1.84*(I14/60)*0.01 -> 7.9049626 | L14: =E14*H14*1.84*(I14/60)*0.01 -> 9.0721383 | M14: 10.487805 | N14: 0.00069787805 | O14: 68.166667 | P14: =M14*N14*1.84*(O14/60)*0.01 -> 0.00015300399 | Q14: =IFERROR(J14-$P14,0) -> 5.3582445 | R14: =IFERROR(K14-$P14,0) -> 7.9048096 | S14: =IFERROR(L14-$P14,0) -> 9.0719853 | T14: =Q14+T13 -> 43.246269 | U14: =R14+U13 -> 63.799698 | V14: =S14+V13 -> 73.220019 | W14: =IFERROR(ROUND(Q14/J14*100,2),0) -> 100 | X14: =IFERROR(ROUND(R14/K14*100,2),0) -> 100 | Y14: =IFERROR(ROUND(S14/L14*100,2),0) -> 100 | Z14: 1.3312568 | AA14: 53.88 | AB14: 61 | AC14: =ROUND(Z14*AA14*1.84*(AB14/60)*0.01,2) -> 1.34 | AD14: =AC14+AD13 -> 5.3965248 | AE14: =IFERROR(ROUND($AC14/Q14*100,2),0) -> 25.01 | AF14: =IFERROR(ROUND($AC14/R14*100,2),0) -> 16.95 | AG14: =IFERROR(ROUND($AC14/S14*100,2),0) -> 14.77
A15: 45922 | B15: 9 | C15: 0.24791667 | D15: =C15+D14 -> 2.4520833 | E15: 18.865612 | F15: 10.1 | G15: 14.9 | H15: 17.1 | I15: 78.833333 | J15: =E15*F15*1.84*(I15/60)*0.01 -> 4.6064751 | K15: =E15*G15*1.84*(I15/60)*0.01 -> 6.795691 | L15: =E15*H15*1.84*(I15/60)*0.01 -> 7.7990817 | M15: 12.860759 | N15: 0.00074373418 | O15: 78.833333 | P15: =M15*N15*1.84*(O15/60)*0.01 -> 0.00023123886 | Q15: =IFERROR(J15-$P15,0) -> 4.6062439 | R15: =IFERROR(K15-$P15,0) -> 6.7954598 | S15: =IFERROR(L15-$P15,0) -> 7.7988504 | T15: =Q15+T14 -> 47.852513 | U15: =R15+U14 -> 70.595157 | V15: =S15+V14 -> 81.018869 | W15: =IFERROR(ROUND(Q15/J15*100,2),0) -> 99.99 | X15: =IFERROR(ROUND(R15/K15*100,2),0) -> 100 | Y15: =IFERROR(ROUND(S15/L15*100,2),0) -> 100 | Z15: 0.98292683 | AA15: 53.88 | AB15: 41 | AC15: =ROUND(Z15*AA15*1.84*(AB15/60)*0.01,2) -> 0.67 | AD15: =AC15+AD14 -> 6.0665248 | AE15: =IFERROR(ROUND($AC15/Q15*100,2),0) -> 14.55 | AF15: =IFERROR(ROUND($AC15/R15*100,2),0) -> 9.86 | AG15: =IFERROR(ROUND($AC15/S15*100,2),0) -> 8.59
A16: 45924 | B16: 10 | C16: 0.25416667 | D16: =C16+D15 -> 2.70625 | E16: 19.039614 | F16: 10.1 | G16: 14.9 | H16: 17.1 | I16: 68.833333 | J16: =E16*F16*1.84*(I16/60)*0.01 -> 4.0592414 | K16: =E16*G16*1.84*(I16/60)*0.01 -> 5.9883858 | L16: =E16*H16*1.84*(I16/60)*0.01 -> 6.872577 | M16: 8.1698068 | N16: 0.0027598068 | O16: 68.833333 | P16: =M16*N16*1.84*(O16/60)*0.01 -> 0.00047594397 | Q16: =IFERROR(J16-$P16,0) -> 4.0587654 | R16: =IFERROR(K16-$P16,0) -> 5.9879098 | S16: =IFERROR(L16-$P16,0) -> 6.872101 | T16: =Q16+T15 -> 51.911279 | U16: =R16+U15 -> 76.583067 | V16: =S16+V15 -> 87.89097 | W16: =IFERROR(ROUND(Q16/J16*100,2),0) -> 99.99 | X16: =IFERROR(ROUND(R16/K16*100,2),0) -> 99.99 | Y16: =IFERROR(ROUND(S16/L16*100,2),0) -> 99.99 | Z16: 0.35327869 | AA16: 53.88 | AB16: 61 | AC16: =ROUND(Z16*AA16*1.84*(AB16/60)*0.01,2) -> 0.36 | AD16: =AC16+AD15 -> 6.4265248 | AE16: =IFERROR(ROUND($AC16/Q16*100,2),0) -> 8.87 | AF16: =IFERROR(ROUND($AC16/R16*100,2),0) -> 6.01 | AG16: =IFERROR(ROUND($AC16/S16*100,2),0) -> 5.24
A17: 45925 | B17: 11 | C17: 0.22361111 | D17: =C17+D16 -> 2.9298611 | E17: 17.254264 | F17: 10.1 | G17: 14.9 | H17: 17.1 | I17: 64.333333 | J17: =E17*F17*1.84*(I17/60)*0.01 -> 3.4381152 | K17: =E17*G17*1.84*(I17/60)*0.01 -> 5.072071 | L17: =E17*H17*1.84*(I17/60)*0.01 -> 5.8209674 | M17: 15.471318 | N17: 0.0008803876 | O17: 64.333333 | P17: =M17*N17*1.84*(O17/60)*0.01 -> 0.00026872239 | Q17: =IFERROR(J17-$P17,0) -> 3.4378465 | R17: =IFERROR(K17-$P17,0) -> 5.0718023 | S17: =IFERROR(L17-$P17,0) -> 5.8206987 | T17: =Q17+T16 -> 55.349125 | U17: =R17+U16 -> 81.65487 | V17: =S17+V16 -> 93.711669 | W17: =IFERROR(ROUND(Q17/J17*100,2),0) -> 99.99 | X17: =IFERROR(ROUND(R17/K17*100,2),0) -> 99.99 | Y17: =IFERROR(ROUND(S17/L17*100,2),0) -> 100 | Z17: 0.61743169 | AA17: 53.88 | AB17: 61 | AC17: =ROUND(Z17*AA17*1.84*(AB17/60)*0.01,2) -> 0.62 | AD17: =AC17+AD16 -> 7.0465248 | AE17: =IFERROR(ROUND($AC17/Q17*100,2),0) -> 18.03 | AF17: =IFERROR(ROUND($AC17/R17*100,2),0) -> 12.22 | AG17: =IFERROR(ROUND($AC17/S17*100,2),0) -> 10.65
A18: 45926 | B18: 12 | C18: 0.21527778 | D18: =C18+D17 -> 3.1451389 | E18: 18.801327 | F18: 10.1 | G18: 14.9 | H18: 17.1 | I18: 75.166667 | J18: =E18*F18*1.84*(I18/60)*0.01 -> 4.377254 | K18: =E18*G18*1.84*(I18/60)*0.01 -> 6.4575332 | L18: =E18*H18*1.84*(I18/60)*0.01 -> 7.4109944 | M18: 13.846903 | N18: 0.0012424336 | O18: 75.166667 | P18: =M18*N18*1.84*(O18/60)*0.01 -> 0.00039656803 | Q18: =IFERROR(J18-$P18,0) -> 4.3768575 | R18: =IFERROR(K18-$P18,0) -> 6.4571366 | S18: =IFERROR(L18-$P18,0) -> 7.4105979 | T18: =Q18+T17 -> 59.725983 | U18: =R18+U17 -> 88.112006 | V18: =S18+V17 -> 101.12227 | W18: =IFERROR(ROUND(Q18/J18*100,2),0) -> 99.99 | X18: =IFERROR(ROUND(R18/K18*100,2),0) -> 99.99 | Y18: =IFERROR(ROUND(S18/L18*100,2),0) -> 99.99 | Z18: 0.71112022 | AA18: 53.88 | AB18: 61 | AC18: =ROUND(Z18*AA18*1.84*(AB18/60)*0.01,2) -> 0.72 | AD18: =AC18+AD17 -> 7.7665248 | AE18: =IFERROR(ROUND($AC18/Q18*100,2),0) -> 16.45 | AF18: =IFERROR(ROUND($AC18/R18*100,2),0) -> 11.15 | AG18: =IFERROR(ROUND($AC18/S18*100,2),0) -> 9.72
A19: 45929 | B19: 13 | C19: 0.25277778 | D19: =C19+D18 -> 3.3979167 | E19: 16.914676 | F19: 10.1 | G19: 14.9 | H19: 17.1 | I19: 97.5 | J19: =E19*F19*1.84*(I19/60)*0.01 -> 5.1080629 | K19: =E19*G19*1.84*(I19/60)*0.01 -> 7.5356572 | L19: =E19*H19*1.84*(I19/60)*0.01 -> 8.6483046 | M19: 8.1744027 | N19: 0.00047220137 | O19: 97.5 | P19: =M19*N19*1.84*(O19/60)*0.01 -> 0.00011541293 | Q19: =IFERROR(J19-$P19,0) -> 5.1079475 | R19: =IFERROR(K19-$P19,0) -> 7.5355418 | S19: =IFERROR(L19-$P19,0) -> 8.6481892 | T19: =Q19+T18 -> 64.83393 | U19: =R19+U18 -> 95.647548 | V19: =S19+V18 -> 109.77046 | W19: =IFERROR(ROUND(Q19/J19*100,2),0) -> 100 | X19: =IFERROR(ROUND(R19/K19*100,2),0) -> 100 | Y19: =IFERROR(ROUND(S19/L19*100,2),0) -> 100 | Z19: 0.64997268 | AA19: 53.88 | AB19: 61 | AC19: =ROUND(Z19*AA19*1.84*(AB19/60)*0.01,2) -> 0.66 | AD19: =AC19+AD18 -> 8.4265248 | AE19: =IFERROR(ROUND($AC19/Q19*100,2),0) -> 12.92 | AF19: =IFERROR(ROUND($AC19/R19*100,2),0) -> 8.76 | AG19: =IFERROR(ROUND($AC19/S19*100,2),0) -> 7.63
A20: 45930 | B20: 14 | C20: 0.27291667 | D20: =C20+D19 -> 3.6708333 | E20: 16.450639 | F20: 10.1 | G20: 14.9 | H20: 17.1 | I20: 65 | J20: =E20*F20*1.84*(I20/60)*0.01 -> 3.3119524 | K20: =E20*G20*1.84*(I20/60)*0.01 -> 4.8859496 | L20: =E20*H20*1.84*(I20/60)*0.01 -> 5.6073649 | M20: 11.693095 | N20: 0.0012670844 | O20: 65 | P20: =M20*N20*1.84*(O20/60)*0.01 -> 0.00029533501 | Q20: =IFERROR(J20-$P20,0) -> 3.3116571 | R20: =IFERROR(K20-$P20,0) -> 4.8856542 | S20: =IFERROR(L20-$P20,0) -> 5.6070696 | T20: =Q20+T19 -> 68.145587 | U20: =R20+U19 -> 100.5332 | V20: =S20+V19 -> 115.37753 | W20: =IFERROR(ROUND(Q20/J20*100,2),0) -> 99.99 | X20: =IFERROR(ROUND(R20/K20*100,2),0) -> 99.99 | Y20: =IFERROR(ROUND(S20/L20*100,2),0) -> 99.99 | Z20: 0.63377049 | AA20: 53.88 | AB20: 61 | AC20: =ROUND(Z20*AA20*1.84*(AB20/60)*0.01,2) -> 0.64 | AD20: =AC20+AD19 -> 9.0665248 | AE20: =IFERROR(ROUND($AC20/Q20*100,2),0) -> 19.33 | AF20: =IFERROR(ROUND($AC20/R20*100,2),0) -> 13.1 | AG20: =IFERROR(ROUND($AC20/S20*100,2),0) -> 11.41
A21: 45931 | B21: 15 | C21: 0.21944444 | D21: =C21+D20 -> 3.8902778 | E21: 14.8 | F21: 10.1 | G21: 14.9 | H21: 17.1 | I21: 50 | J21: =E21*F21*1.84*(I21/60)*0.01 -> 2.2920267 | K21: =E21*G21*1.84*(I21/60)*0.01 -> 3.3813067 | L21: =E21*H21*1.84*(I21/60)*0.01 -> 3.88056 | M21: 11.76 | N21: 0.006 | O21: 50 | P21: =M21*N21*1.84*(O21/60)*0.01 -> 0.00108192 | Q21: =IFERROR(J21-$P21,0) -> 2.2909447 | R21: =IFERROR(K21-$P21,0) -> 3.3802247 | S21: =IFERROR(L21-$P21,0) -> 3.8794781 | T21: =Q21+T20 -> 70.436532 | U21: =R21+U20 -> 103.91343 | V21: =S21+V20 -> 119.257 | W21: =IFERROR(ROUND(Q21/J21*100,2),0) -> 99.95 | X21: =IFERROR(ROUND(R21/K21*100,2),0) -> 99.97 | Y21: =IFERROR(ROUND(S21/L21*100,2),0) -> 99.97 | Z21: 0.6602459 | AA21: 53.88 | AB21: 61 | AC21: =ROUND(Z21*AA21*1.84*(AB21/60)*0.01,2) -> 0.67 | AD21: =AC21+AD20 -> 9.7365248 | AE21: =IFERROR(ROUND($AC21/Q21*100,2),0) -> 29.25 | AF21: =IFERROR(ROUND($AC21/R21*100,2),0) -> 19.82 | AG21: =IFERROR(ROUND($AC21/S21*100,2),0) -> 17.27
A22: 45932 | B22: 16 | C22: 0.27083333 | D22: =C22+D21 -> 4.1611111 | E22: 17.334862 | F22: 10.1 | G22: 14.9 | H22: 17.1 | I22: 108.83333 | J22: =E22*F22*1.84*(I22/60)*0.01 -> 5.8434627 | K22: =E22*G22*1.84*(I22/60)*0.01 -> 8.6205539 | L22: =E22*H22*1.84*(I22/60)*0.01 -> 9.8933873 | M22: 9.4954128 | N22: 0.00086227829 | O22: 108.83333 | P22: =M22*N22*1.84*(O22/60)*0.01 -> 0.00027326865 | Q22: =IFERROR(J22-$P22,0) -> 5.8431894 | R22: =IFERROR(K22-$P22,0) -> 8.6202806 | S22: =IFERROR(L22-$P22,0) -> 9.8931141 | T22: =Q22+T21 -> 76.279721 | U22: =R22+U21 -> 112.53371 | V22: =S22+V21 -> 129.15012 | W22: =IFERROR(ROUND(Q22/J22*100,2),0) -> 100 | X22: =IFERROR(ROUND(R22/K22*100,2),0) -> 100 | Y22: =IFERROR(ROUND(S22/L22*100,2),0) -> 100 | Z22: 0.46010929 | AA22: 53.88 | AB22: 61 | AC22: =ROUND(Z22*AA22*1.84*(AB22/60)*0.01,2) -> 0.46 | AD22: =AC22+AD21 -> 10.196525 | AE22: =IFERROR(ROUND($AC22/Q22*100,2),0) -> 7.87 | AF22: =IFERROR(ROUND($AC22/R22*100,2),0) -> 5.34 | AG22: =IFERROR(ROUND($AC22/S22*100,2),0) -> 4.65
A23: 45936 | B23: 17 | C23: 0.18472222 | D23: =C23+D22 -> 4.3458333 | E23: - | F23: 10.1 | G23: 14.9 | H23: 17.1 | I23: - | J23: - | K23: - | L23: - | M23: - | N23: - | O23: - | P23: - | Q23: =IFERROR(J23-$P23,0) -> 0 | R23: =IFERROR(K23-$P23,0) -> 0 | S23: =IFERROR(L23-$P23,0) -> 0 | T23: =Q23+T22 -> 76.279721 | U23: =R23+U22 -> 112.53371 | V23: =S23+V22 -> 129.15012 | Z23: 0.36491935 | AA23: 53.88 | AB23: 62 | AC23: =ROUND(Z23*AA23*1.84*(AB23/60)*0.01,2) -> 0.37 | AD23: =AC23+AD22 -> 10.566525 | AE23: =IFERROR(ROUND($AC23/Q23*100,2),0) -> 0 | AF23: =IFERROR(ROUND($AC23/R23*100,2),0) -> 0 | AG23: =IFERROR(ROUND($AC23/S23*100,2),0) -> 0
A24: 45939 | B24: 18 | C24: 0.24166667 | D24: =C24+D23 -> 4.5875 | E24: 16.920426 | F24: 10.1 | G24: 14.9 | H24: 17.1 | I24: 78.166667 | J24: =E24*F24*1.84*(I24/60)*0.01 -> 4.0965741 | K24: =E24*G24*1.84*(I24/60)*0.01 -> 6.0434609 | L24: =E24*H24*1.84*(I24/60)*0.01 -> 6.9357839 | M24: 14.8 | N24: 0.0020828723 | O24: 78.166667 | P24: =M24*N24*1.84*(O24/60)*0.01 -> 0.00073894571 | Q24: =IFERROR(J24-$P24,0) -> 4.0958352 | R24: =IFERROR(K24-$P24,0) -> 6.0427219 | S24: =IFERROR(L24-$P24,0) -> 6.935045 | T24: =Q24+T23 -> 80.375557 | U24: =R24+U23 -> 118.57643 | V24: =S24+V23 -> 136.08516 | W24: =IFERROR(ROUND(Q24/J24*100,2),0) -> 99.98 | X24: =IFERROR(ROUND(R24/K24*100,2),0) -> 99.99 | Y24: =IFERROR(ROUND(S24/L24*100,2),0) -> 99.99 | Z24: 0.58185792 | AA24: 53.88 | AB24: 61 | AC24: =ROUND(Z24*AA24*1.84*(AB24/60)*0.01,2) -> 0.59 | AD24: =AC24+AD23 -> 11.156525 | AE24: =IFERROR(ROUND($AC24/Q24*100,2),0) -> 14.4 | AF24: =IFERROR(ROUND($AC24/R24*100,2),0) -> 9.76 | AG24: =IFERROR(ROUND($AC24/S24*100,2),0) -> 8.51
A25: 45940 | B25: 19 | C25: 0.22291667 | D25: =C25+D24 -> 4.8104167 | E25: 18.121246 | F25: 10.1 | G25: 14.9 | H25: 17.1 | I25: 58.666667 | J25: =E25*F25*1.84*(I25/60)*0.01 -> 3.2928157 | K25: =E25*G25*1.84*(I25/60)*0.01 -> 4.8577182 | L25: =E25*H25*1.84*(I25/60)*0.01 -> 5.5749652 | M25: 10.065156 | N25: 0.0036769688 | O25: 58.666667 | P25: =M25*N25*1.84*(O25/60)*0.01 -> 0.00066583779 | Q25: =IFERROR(J25-$P25,0) -> 3.2921499 | R25: =IFERROR(K25-$P25,0) -> 4.8570524 | S25: =IFERROR(L25-$P25,0) -> 5.5742994 | T25: =Q25+T24 -> 83.667706 | U25: =R25+U24 -> 123.43348 | V25: =S25+V24 -> 141.65946 | W25: =IFERROR(ROUND(Q25/J25*100,2),0) -> 99.98 | X25: =IFERROR(ROUND(R25/K25*100,2),0) -> 99.99 | Y25: =IFERROR(ROUND(S25/L25*100,2),0) -> 99.99 | Z25: 0.62551913 | AA25: 53.88 | AB25: 61 | AC25: =ROUND(Z25*AA25*1.84*(AB25/60)*0.01,2) -> 0.63 | AD25: =AC25+AD24 -> 11.786525 | AE25: =IFERROR(ROUND($AC25/Q25*100,2),0) -> 19.14 | AF25: =IFERROR(ROUND($AC25/R25*100,2),0) -> 12.97 | AG25: =IFERROR(ROUND($AC25/S25*100,2),0) -> 11.3
A26: 45944 | B26: 20 | C26: 0.21666667 | D26: =C26+D25 -> 5.0270833 | E26: 19.65 | F26: 10.1 | G26: 14.9 | H26: 17.1 | I26: 110 | J26: =E26*F26*1.84*(I26/60)*0.01 -> 6.694886 | K26: =E26*G26*1.84*(I26/60)*0.01 -> 9.876614 | L26: =E26*H26*1.84*(I26/60)*0.01 -> 11.334906 | M26: 14.8 | N26: 0.0014 | O26: 110 | P26: =M26*N26*1.84*(O26/60)*0.01 -> 0.00069895467 | Q26: =IFERROR(J26-$P26,0) -> 6.694187 | R26: =IFERROR(K26-$P26,0) -> 9.875915 | S26: =IFERROR(L26-$P26,0) -> 11.334207 | T26: =Q26+T25 -> 90.361894 | U26: =R26+U25 -> 133.3094 | V26: =S26+V25 -> 152.99367 | W26: =IFERROR(ROUND(Q26/J26*100,2),0) -> 99.99 | X26: =IFERROR(ROUND(R26/K26*100,2),0) -> 99.99 | Y26: =IFERROR(ROUND(S26/L26*100,2),0) -> 99.99 | Z26: 0.43521858 | AA26: 53.88 | AB26: 61 | AC26: =ROUND(Z26*AA26*1.84*(AB26/60)*0.01,2) -> 0.44 | AD26: =AC26+AD25 -> 12.226525 | AE26: =IFERROR(ROUND($AC26/Q26*100,2),0) -> 6.57 | AF26: =IFERROR(ROUND($AC26/R26*100,2),0) -> 4.46 | AG26: =IFERROR(ROUND($AC26/S26*100,2),0) -> 3.88
A27: 45945 | B27: 21 | C27: 0.17777778 | D27: =C27+D26 -> 5.2048611 | E27: 18.71 | F27: 10.1 | G27: 14.9 | H27: 17.1 | I27: 48 | J27: =E27*F27*1.84*(I27/60)*0.01 -> 2.7816531 | K27: =E27*G27*1.84*(I27/60)*0.01 -> 4.1036269 | L27: =E27*H27*1.84*(I27/60)*0.01 -> 4.7095315 | M27: 14.8 | N27: 0.01 | O27: 48 | P27: =M27*N27*1.84*(O27/60)*0.01 -> 0.00217856 | Q27: =IFERROR(J27-$P27,0) -> 2.7794746 | R27: =IFERROR(K27-$P27,0) -> 4.1014483 | S27: =IFERROR(L27-$P27,0) -> 4.707353 | T27: =Q27+T26 -> 93.141368 | U27: =R27+U26 -> 137.41085 | V27: =S27+V26 -> 157.70102 | W27: =IFERROR(ROUND(Q27/J27*100,2),0) -> 99.92 | X27: =IFERROR(ROUND(R27/K27*100,2),0) -> 99.95 | Y27: =IFERROR(ROUND(S27/L27*100,2),0) -> 99.95 | Z27: 0.44204918 | AA27: 53.88 | AB27: 61 | AC27: =ROUND(Z27*AA27*1.84*(AB27/60)*0.01,2) -> 0.45 | AD27: =AC27+AD26 -> 12.676525 | AE27: =IFERROR(ROUND($AC27/Q27*100,2),0) -> 16.19 | AF27: =IFERROR(ROUND($AC27/R27*100,2),0) -> 10.97 | AG27: =IFERROR(ROUND($AC27/S27*100,2),0) -> 9.56
A28: 45946 | B28: 22 | C28: 0.20486111 | D28: =C28+D27 -> 5.4097222 | E28: 18.3 | F28: 10.1 | G28: 14.9 | H28: 17.1 | I28: 40.166667 | J28: =E28*F28*1.84*(I28/60)*0.01 -> 2.2766949 | K28: =E28*G28*1.84*(I28/60)*0.01 -> 3.3586885 | L28: =E28*H28*1.84*(I28/60)*0.01 -> 3.8546022 | M28: 11.938017 | N28: 0.0014825207 | O28: 40.166667 | P28: =M28*N28*1.84*(O28/60)*0.01 -> 0.00021800442 | Q28: =IFERROR(J28-$P28,0) -> 2.2764769 | R28: =IFERROR(K28-$P28,0) -> 3.3584705 | S28: =IFERROR(L28-$P28,0) -> 3.8543842 | T28: =Q28+T27 -> 95.417845 | U28: =R28+U27 -> 140.76932 | V28: =S28+V27 -> 161.55541 | W28: =IFERROR(ROUND(Q28/J28*100,2),0) -> 99.99 | X28: =IFERROR(ROUND(R28/K28*100,2),0) -> 99.99 | Y28: =IFERROR(ROUND(S28/L28*100,2),0) -> 99.99 | Z28: 0.53855191 | AA28: 53.88 | AB28: 61 | AC28: =ROUND(Z28*AA28*1.84*(AB28/60)*0.01,2) -> 0.54 | AD28: =AC28+AD27 -> 13.216525 | AE28: =IFERROR(ROUND($AC28/Q28*100,2),0) -> 23.72 | AF28: =IFERROR(ROUND($AC28/R28*100,2),0) -> 16.08 | AG28: =IFERROR(ROUND($AC28/S28*100,2),0) -> 14.01
A29: 45947 | B29: 23 | C29: 0.21597222 | D29: =C29+D28 -> 5.6256944 | E29: 25.425342 | F29: 10.1 | G29: 14.9 | H29: 17.1 | I29: 48.5 | J29: =E29*F29*1.84*(I29/60)*0.01 -> 3.8194119 | K29: =E29*G29*1.84*(I29/60)*0.01 -> 5.6345779 | L29: =E29*H29*1.84*(I29/60)*0.01 -> 6.4665291 | M29: 10.1 | N29: 0.0019673288 | O29: 48.5 | P29: =M29*N29*1.84*(O29/60)*0.01 -> 0.00029553344 | Q29: =IFERROR(J29-$P29,0) -> 3.8191164 | R29: =IFERROR(K29-$P29,0) -> 5.6342824 | S29: =IFERROR(L29-$P29,0) -> 6.4662335 | T29: =Q29+T28 -> 99.236961 | U29: =R29+U28 -> 146.4036 | V29: =S29+V28 -> 168.02164 | W29: =IFERROR(ROUND(Q29/J29*100,2),0) -> 99.99 | X29: =IFERROR(ROUND(R29/K29*100,2),0) -> 99.99 | Y29: =IFERROR(ROUND(S29/L29*100,2),0) -> 100 | Z29: 0.51671717 | AA29: 53.88 | AB29: 66 | AC29: =ROUND(Z29*AA29*1.84*(AB29/60)*0.01,2) -> 0.56 | AD29: =AC29+AD28 -> 13.776525 | AE29: =IFERROR(ROUND($AC29/Q29*100,2),0) -> 14.66 | AF29: =IFERROR(ROUND($AC29/R29*100,2),0) -> 9.94 | AG29: =IFERROR(ROUND($AC29/S29*100,2),0) -> 8.66
A30: 45950 | B30: 24 | C30: 0.22777778 | D30: =C30+D29 -> 5.8534722 | E30: 12.457407 | F30: 10.1 | G30: 14.9 | H30: 17.1 | I30: 53.833333 | J30: =E30*F30*1.84*(I30/60)*0.01 -> 2.0771453 | K30: =E30*G30*1.84*(I30/60)*0.01 -> 3.0643035 | L30: =E30*H30*1.84*(I30/60)*0.01 -> 3.516751 | M30: 14.8 | N30: 0.0063147222 | O30: 53.833333 | P30: =M30*N30*1.84*(O30/60)*0.01 -> 0.0015428859 | Q30: =IFERROR(J30-$P30,0) -> 2.0756025 | R30: =IFERROR(K30-$P30,0) -> 3.0627606 | S30: =IFERROR(L30-$P30,0) -> 3.5152081 | T30: =Q30+T29 -> 101.31256 | U30: =R30+U29 -> 149.46636 | V30: =S30+V29 -> 171.53685 | W30: =IFERROR(ROUND(Q30/J30*100,2),0) -> 99.93 | X30: =IFERROR(ROUND(R30/K30*100,2),0) -> 99.95 | Y30: =IFERROR(ROUND(S30/L30*100,2),0) -> 99.96 | Z30: 0.22681818 | AA30: 53.88 | AB30: 66 | AC30: =ROUND(Z30*AA30*1.84*(AB30/60)*0.01,2) -> 0.25 | AD30: =AC30+AD29 -> 14.026525 | AE30: =IFERROR(ROUND($AC30/Q30*100,2),0) -> 12.04 | AF30: =IFERROR(ROUND($AC30/R30*100,2),0) -> 8.16 | AG30: =IFERROR(ROUND($AC30/S30*100,2),0) -> 7.11
A31: 45951 | B31: 25 | C31: 0.2125 | D31: =C31+D30 -> 6.0659722 | E31: 18.2891 | F31: 10.1 | G31: 14.9 | H31: 17.1 | I31: 35 | J31: =E31*F31*1.84*(I31/60)*0.01 -> 1.9826603 | K31: =E31*G31*1.84*(I31/60)*0.01 -> 2.9249147 | L31: =E31*H31*1.84*(I31/60)*0.01 -> 3.3567813 | M31: 14.9 | N31: 0.0010243128 | O31: 35 | P31: =M31*N31*1.84*(O31/60)*0.01 -> 0.00016381493 | Q31: =IFERROR(J31-$P31,0) -> 1.9824965 | R31: =IFERROR(K31-$P31,0) -> 2.9247509 | S31: =IFERROR(L31-$P31,0) -> 3.3566175 | T31: =Q31+T30 -> 103.29506 | U31: =R31+U30 -> 152.39111 | V31: =S31+V30 -> 174.89347 | W31: =IFERROR(ROUND(Q31/J31*100,2),0) -> 99.99 | X31: =IFERROR(ROUND(R31/K31*100,2),0) -> 99.99 | Y31: =IFERROR(ROUND(S31/L31*100,2),0) -> 100 | Z31: 0.20186567 | AA31: 53.88 | AB31: 67 | AC31: =ROUND(Z31*AA31*1.84*(AB31/60)*0.01,2) -> 0.22 | AD31: =AC31+AD30 -> 14.246525 | AE31: =IFERROR(ROUND($AC31/Q31*100,2),0) -> 11.1 | AF31: =IFERROR(ROUND($AC31/R31*100,2),0) -> 7.52 | AG31: =IFERROR(ROUND($AC31/S31*100,2),0) -> 6.55
A32: 45954 | B32: 26 | C32: 0.23958333 | D32: =C32+D31 -> 6.3055556 | E32: 19.09 | F32: 10.1 | G32: 14.9 | H32: 17.1 | I32: 36.17 | J32: =E32*F32*1.84*(I32/60)*0.01 -> 2.1386631 | K32: =E32*G32*1.84*(I32/60)*0.01 -> 3.1550575 | L32: =E32*H32*1.84*(I32/60)*0.01 -> 3.6209049 | M32: 14.93 | N32: 0.001354 | O32: 36.17 | P32: =M32*N32*1.84*(O32/60)*0.01 -> 0.00022422992 | Q32: =IFERROR(J32-$P32,0) -> 2.1384389 | R32: =IFERROR(K32-$P32,0) -> 3.1548333 | S32: =IFERROR(L32-$P32,0) -> 3.6206807 | T32: =Q32+T31 -> 105.4335 | U32: =R32+U31 -> 155.54594 | V32: =S32+V31 -> 178.51415 | W32: =IFERROR(ROUND(Q32/J32*100,2),0) -> 99.99 | X32: =IFERROR(ROUND(R32/K32*100,2),0) -> 99.99 | Y32: =IFERROR(ROUND(S32/L32*100,2),0) -> 99.99 | Z32: 0.2245082 | AA32: 53.88 | AB32: 61 | AC32: =ROUND(Z32*AA32*1.84*(AB32/60)*0.01,2) -> 0.23 | AD32: =AC32+AD31 -> 14.476525 | AE32: =IFERROR(ROUND($AC32/Q32*100,2),0) -> 10.76 | AF32: =IFERROR(ROUND($AC32/R32*100,2),0) -> 7.29 | AG32: =IFERROR(ROUND($AC32/S32*100,2),0) -> 6.35
A33: 45957 | B33: 27 | C33: 0.19930556 | D33: =C33+D32 -> 6.5048611 | E33: 24.775 | F33: 10.1 | G33: 14.9 | H33: 17.1 | I33: 27.833333 | J33: =E33*F33*1.84*(I33/60)*0.01 -> 2.1358307 | K33: =E33*G33*1.84*(I33/60)*0.01 -> 3.150879 | L33: =E33*H33*1.84*(I33/60)*0.01 -> 3.6161094 | M33: 15.1 | N33: 0.0007927381 | O33: 27.833333 | P33: =M33*N33*1.84*(O33/60)*0.01 -> 0.00010217355 | Q33: =IFERROR(J33-$P33,0) -> 2.1357286 | R33: =IFERROR(K33-$P33,0) -> 3.1507768 | S33: =IFERROR(L33-$P33,0) -> 3.6160073 | T33: =Q33+T32 -> 107.56923 | U33: =R33+U32 -> 158.69672 | V33: =S33+V32 -> 182.13015 | W33: =IFERROR(ROUND(Q33/J33*100,2),0) -> 100 | X33: =IFERROR(ROUND(R33/K33*100,2),0) -> 100 | Y33: =IFERROR(ROUND(S33/L33*100,2),0) -> 100 | Z33: 0.2 | AA33: 53.88 | AB33: 61 | AC33: =ROUND(Z33*AA33*1.84*(AB33/60)*0.01,2) -> 0.2 | AD33: =AC33+AD32 -> 14.676525 | AE33: =IFERROR(ROUND($AC33/Q33*100,2),0) -> 9.36 | AF33: =IFERROR(ROUND($AC33/R33*100,2),0) -> 6.35 | AG33: =IFERROR(ROUND($AC33/S33*100,2),0) -> 5.53
A34: 45958 | B34: 28 | C34: 0.22083333 | D34: =C34+D33 -> 6.7256944 | E34: 24.95 | F34: 10.1 | G34: 14.9 | H34: 17.1 | I34: 27.833333 | J34: =E34*F34*1.84*(I34/60)*0.01 -> 2.1509173 | K34: =E34*G34*1.84*(I34/60)*0.01 -> 3.1731355 | L34: =E34*H34*1.84*(I34/60)*0.01 -> 3.6416521 | M34: 15.1 | N34: 0.0011010714 | O34: 27.833333 | P34: =M34*N34*1.84*(O34/60)*0.01 -> 0.00014191367 | Q34: =IFERROR(J34-$P34,0) -> 2.1507754 | R34: =IFERROR(K34-$P34,0) -> 3.1729935 | S34: =IFERROR(L34-$P34,0) -> 3.6415102 | T34: =Q34+T33 -> 109.72 | U34: =R34+U33 -> 161.86971 | V34: =S34+V33 -> 185.77166 | W34: =IFERROR(ROUND(Q34/J34*100,2),0) -> 99.99 | X34: =IFERROR(ROUND(R34/K34*100,2),0) -> 100 | Y34: =IFERROR(ROUND(S34/L34*100,2),0) -> 100 | Z34: 0.25296875 | AA34: 53.88 | AB34: 64 | AC34: =ROUND(Z34*AA34*1.84*(AB34/60)*0.01,2) -> 0.27 | AD34: =AC34+AD33 -> 14.946525 | AE34: =IFERROR(ROUND($AC34/Q34*100,2),0) -> 12.55 | AF34: =IFERROR(ROUND($AC34/R34*100,2),0) -> 8.51 | AG34: =IFERROR(ROUND($AC34/S34*100,2),0) -> 7.41
A35: 45959 | B35: 29 | C35: 0.25486111 | D35: =C35+D34 -> 6.9805556 | E35: 24.49 | F35: 10.1 | G35: 14.9 | H35: 17.1 | I35: 80.55 | J35: =E35*F35*1.84*(I35/60)*0.01 -> 6.110015 | K35: =E35*G35*1.84*(I35/60)*0.01 -> 9.0137845 | L35: =E35*H35*1.84*(I35/60)*0.01 -> 10.344679 | M35: 15.1 | N35: 0.006 | O35: 80.5 | P35: =M35*N35*1.84*(O35/60)*0.01 -> 0.002236612 | Q35: =IFERROR(J35-$P35,0) -> 6.1077784 | R35: =IFERROR(K35-$P35,0) -> 9.0115479 | S35: =IFERROR(L35-$P35,0) -> 10.342442 | T35: =Q35+T34 -> 115.82778 | U35: =R35+U34 -> 170.88126 | V35: =S35+V34 -> 196.11411 | W35: =IFERROR(ROUND(Q35/J35*100,2),0) -> 99.96 | X35: =IFERROR(ROUND(R35/K35*100,2),0) -> 99.98 | Y35: =IFERROR(ROUND(S35/L35*100,2),0) -> 99.98 | Z35: 0.2 | AA35: 53.88 | AB35: 61 | AC35: =ROUND(Z35*AA35*1.84*(AB35/60)*0.01,2) -> 0.2 | AD35: =AC35+AD34 -> 15.146525 | AE35: =IFERROR(ROUND($AC35/Q35*100,2),0) -> 3.27 | AF35: =IFERROR(ROUND($AC35/R35*100,2),0) -> 2.22 | AG35: =IFERROR(ROUND($AC35/S35*100,2),0) -> 1.93
A36: 45960 | B36: 30 | C36: 0.18958333 | D36: =C36+D35 -> 7.1701389 | E36: 26.544 | F36: 10.1 | G36: 14.9 | H36: 17.1 | I36: 24.833333 | J36: =E36*F36*1.84*(I36/60)*0.01 -> 2.0416878 | K36: =E36*G36*1.84*(I36/60)*0.01 -> 3.0119949 | L36: =E36*H36*1.84*(I36/60)*0.01 -> 3.4567189 | M36: 15.1 | N36: 0.0013751333 | O36: 24.833333 | P36: =M36*N36*1.84*(O36/60)*0.01 -> 0.0001581333 | Q36: =IFERROR(J36-$P36,0) -> 2.0415297 | R36: =IFERROR(K36-$P36,0) -> 3.0118367 | S36: =IFERROR(L36-$P36,0) -> 3.4565608 | T36: =Q36+T35 -> 117.86931 | U36: =R36+U35 -> 173.8931 | V36: =S36+V35 -> 199.57067 | W36: =IFERROR(ROUND(Q36/J36*100,2),0) -> 99.99 | X36: =IFERROR(ROUND(R36/K36*100,2),0) -> 99.99 | Y36: =IFERROR(ROUND(S36/L36*100,2),0) -> 100 | Z36: 0.20013661 | AA36: 53.88 | AB36: 61 | AC36: =ROUND(Z36*AA36*1.84*(AB36/60)*0.01,2) -> 0.2 | AD36: =AC36+AD35 -> 15.346525 | AE36: =IFERROR(ROUND($AC36/Q36*100,2),0) -> 9.8 | AF36: =IFERROR(ROUND($AC36/R36*100,2),0) -> 6.64 | AG36: =IFERROR(ROUND($AC36/S36*100,2),0) -> 5.79
A37: Total | C37: =AVERAGE(C7:C36) -> 0.23900463 | D37: =D36 -> 7.1701389 | E37: =AVERAGE(E24:E36) -> 20.59404 | K37: =AVERAGE(K24:K36) -> 4.7206735 | P37: =SUM(P7:P36) -> 0.014073343 | U37: =U36 -> 173.8931 | X37: =ROUND(AVERAGE(X7:X36),2) -> 99.99 | AD37: =AD36 -> 15.346525
B44: Time | Q44: Adsorp | X44: Steam | AI44: Sorbent Aging
AI74: CO2 Capture&Recovery
AI101: CO2 Capture & Conc flue gas in

Sheet Run 2 Gen 1+2
A1: Run 2 Gen 1 + Gen 2
B3: Cycle | C3: Operating Hour | D3: Operating Hour Cumulative Gen 1+2 | E3: CO₂In during adsorption | I3: CO₂Out during adsorption | M3: CO₂ Captured | P3: CO₂Regen during steaming
E4: Q (Nm³/h) | F4: C (vol%) | G4: T (min) | H4: CO₂ (kg) | I4: Q (Nm³/h) | J4: C (vol%) | K4: T (min) | L4: CO₂ (kg) | M4: CO₂ Captured Run 2 Gen 1+2 | N4: CO₂ Captured Run 2 Gen 1+2 Cumulative (Kg) | O4: % Captured | P4: Q (Nm³/h) | Q4: C (vol%) | R4: T (min) | S4: CO₂ (kg) | T4: CO2 Recovery Run 2 Gen 1 +2 Cumulative (Kg) | U4: % Recovery
A5: 45965 | B5: 1 | C5: 0.22777778 | D5: 0.22777778 | E5: 16.998113 | F5: 14.9 | G5: 52.833333 | H5: =ROUND(E5*F5*1.84*(G5/60)*0.01,2) -> 4.1 | I5: 14.332075 | J5: 1.081761e-05 | K5: 52.833333 | L5: =I5*J5*1.84*(K5/60)*0.01 -> 2.5119732e-06 | M5: =H5-L5 -> 4.0999975 | N5: =M5 -> 4.0999975 | O5: =ROUND(M5/H5*100,2) -> 100 | P5: 0.2 | Q5: 53.88 | R5: 70.833333 | S5: =ROUND(P5*Q5*1.84*(R5/60)*0.01,2) -> 0.23 | T5: 0.23 | U5: =IFERROR(ROUND(S5/M5 *100,2),0) -> 5.61
A6: 45967 | B6: 2 | C6: 0.225 | D6: =C6+D5 -> 0.45277778 | E6: 16.026609 | F6: 14.9 | G6: 95.666667 | H6: =ROUND(E6*F6*1.84*(G6/60)*0.01,2) -> 7.01 | I6: 14.249043 | J6: 0.00020572174 | K6: 95.666667 | L6: =I6*J6*1.84*(K6/60)*0.01 -> 8.5998943e-05 | M6: =H6-L6 -> 7.009914 | N6: =N5+M6 -> 11.109911 | O6: =ROUND(M6/H6*100,2) -> 100 | P6: 0.2 | Q6: 53.88 | R6: 41.833333 | S6: =ROUND(P6*Q6*1.84*(R6/60)*0.01,2) -> 0.14 | T6: =T5+S6 -> 0.37 | U6: =IFERROR(ROUND(S6/M6 *100,2),0) -> 2
A7: 45968 | B7: 3 | C7: 0.3125 | D7: =C7+D6 -> 0.76527778 | E7: 16.5 | F7: 14.9 | G7: 82.166667 | H7: =ROUND(E7*F7*1.84*(G7/60)*0.01,2) -> 6.19 | I7: 15.1 | J7: 0.00016753036 | K7: 82.166667 | L7: =I7*J7*1.84*(K7/60)*0.01 -> 6.3743033e-05 | M7: =H7-L7 -> 6.1899363 | N7: =N6+M7 -> 17.299848 | O7: =ROUND(M7/H7*100,2) -> 100 | P7: 0.21124183 | Q7: 53.88 | R7: 50.833333 | S7: =ROUND(P7*Q7*1.84*(R7/60)*0.01,2) -> 0.18 | T7: =T6+S7 -> 0.55 | U7: =IFERROR(ROUND(S7/M7 *100,2),0) -> 2.91
A8: 45972 | B8: 4 | C8: 0.21666667 | D8: =C8+D7 -> 0.98194444 | E8: 16.671429 | F8: 14.9 | G8: 48.833333 | H8: =ROUND(E8*F8*1.84*(G8/60)*0.01,2) -> 3.72 | I8: 14.957483 | J8: 0.0041015306 | K8: 48.833333 | L8: =I8*J8*1.84*(K8/60)*0.01 -> 0.00091872898 | M8: =H8-L8 -> 3.7190813 | N8: =N7+M8 -> 21.018929 | O8: =ROUND(M8/H8*100,2) -> 99.98 | P8: 0.21124183 | Q8: 53.88 | R8: 50.833333 | S8: =ROUND(P8*Q8*1.84*(R8/60)*0.01,2) -> 0.18 | T8: =T7+S8 -> 0.73 | U8: =IFERROR(ROUND(S8/M8 *100,2),0) -> 4.84
A9: 45973 | B9: 5 | C9: 0.22013889 | D9: =C9+D8 -> 1.2020833 | E9: 17.366929 | F9: 14.9 | G9: 63.333333 | H9: =ROUND(E9*F9*1.84*(G9/60)*0.01,2) -> 5.03 | I9: 14.738845 | J9: 0.0016456693 | K9: 63.333333 | L9: =I9*J9*1.84*(K9/60)*0.01 -> 0.00047109114 | M9: =H9-L9 -> 5.0295289 | N9: =N8+M9 -> 26.048458 | O9: =ROUND(M9/H9*100,2) -> 99.99 | P9: 0.2 | Q9: 53.88 | R9: 35.833333 | S9: =ROUND(P9*Q9*1.84*(R9/60)*0.01,2) -> 0.12 | T9: =T8+S9 -> 0.85 | U9: =IFERROR(ROUND(S9/M9 *100,2),0) -> 2.39
A10: 45974 | B10: 6 | C10: 0.26944444 | D10: =C10+D9 -> 1.4715278 | E10: 16.567241 | F10: 14.9 | G10: 115.83333 | H10: =ROUND(E10*F10*1.84*(G10/60)*0.01,2) -> 8.77 | I10: 14.404454 | J10: 1e-05 | K10: 115.83333 | L10: =I10*J10*1.84*(K10/60)*0.01 -> 5.1167822e-06 | M10: =H10-L10 -> 8.7699949 | N10: =N9+M10 -> 34.818453 | O10: =ROUND(M10/H10*100,2) -> 100 | P10: 0.29225926 | Q10: 53.88 | R10: 44.833333 | S10: =ROUND(P10*Q10*1.84*(R10/60)*0.01,2) -> 0.22 | T10: =T9+S10 -> 1.07 | U10: =IFERROR(ROUND(S10/M10 *100,2),0) -> 2.51
A11: 45975 | B11: 7 | C11: 0.28819444 | D11: =C11+D10 -> 1.7597222 | E11: 17.592373 | F11: 14.9 | G11: 117.83333 | H11: =ROUND(E11*F11*1.84*(G11/60)*0.01,2) -> 9.47 | I11: 12.101695 | J11: 1e-05 | K11: 117.83333 | L11: =I11*J11*1.84*(K11/60)*0.01 -> 4.3730147e-06 | M11: =H11-L11 -> 9.4699956 | N11: =N10+M11 -> 44.288448 | O11: =ROUND(M11/H11*100,2) -> 100 | P11: 0.36 | Q11: 53.88 | R11: 60.83 | S11: =ROUND(P11*Q11*1.84*(R11/60)*0.01,2) -> 0.36 | T11: =T10+S11 -> 1.43 | U11: =IFERROR(ROUND(S11/M11 *100,2),0) -> 3.8
A12: 45978 | B12: 8 | C12: 0.27013889 | D12: =C12+D11 -> 2.0298611 | E12: 14.41087 | F12: 14.9 | G12: 137.83333 | H12: =ROUND(E12*F12*1.84*(G12/60)*0.01,2) -> 9.08 | I12: 13.35 | J12: 1e-05 | K12: 137.83333 | L12: =I12*J12*1.84*(K12/60)*0.01 -> 5.6428967e-06 | M12: =H12-L12 -> 9.0799944 | N12: =N11+M12 -> 53.368443 | O12: =ROUND(M12/H12*100,2) -> 100 | P12: 0.45580882 | Q12: 53.88 | R12: 67.833333 | S12: =ROUND(P12*Q12*1.84*(R12/60)*0.01,2) -> 0.51 | T12: =T11+S12 -> 1.94 | U12: =IFERROR(ROUND(S12/M12 *100,2),0) -> 5.62
A13: 45979 | B13: 9 | C13: 0.26388889 | D13: =C13+D12 -> 2.29375 | E13: 17.872727 | F13: 14.9 | G13: 120.83333 | H13: =ROUND(E13*F13*1.84*(G13/60)*0.01,2) -> 9.87 | I13: 12.045455 | J13: 1e-05 | K13: 120.83333 | L13: =I13*J13*1.84*(K13/60)*0.01 -> 4.4635101e-06 | M13: =H13-L13 -> 9.8699955 | N13: =N12+M13 -> 63.238438 | O13: =ROUND(M13/H13*100,2) -> 100 | P13: 0.36 | Q13: 0 | R13: 60.83 | S13: =ROUND(P13*Q13*1.84*(R13/60)*0.01,2) -> 0 | T13: =T12+S13 -> 1.94 | U13: =IFERROR(ROUND(S13/M13 *100,2),0) -> 0
A14: 45980 | B14: 10 | C14: 0.23472222 | D14: =C14+D13 -> 2.5284722 | E14: 18.916484 | F14: 10.977912 | G14: 90.833333 | H14: =ROUND(E14*F14*1.84*(G14/60)*0.01,2) -> 5.78 | I14: 5 | J14: 9.96337e-06 | K14: 90.833333 | L14: =I14*J14*1.84*(K14/60)*0.01 -> 1.387676e-06 | M14: =H14-L14 -> 5.7799986 | N14: =N13+M14 -> 69.018437 | O14: =ROUND(M14/H14*100,2) -> 100 | P14: 0.29942623 | Q14: 66.83 | R14: 60.833333 | S14: =ROUND(P14*Q14*1.84*(R14/60)*0.01,2) -> 0.37 | T14: =T13+S14 -> 2.31 | U14: =IFERROR(ROUND(S14/M14 *100,2),0) -> 6.4
A15: 45981 | B15: 11 | C15: 0.25277778 | D15: =C15+D14 -> 2.78125 | E15: 11.231 | F15: 2.6081 | G15: 99.833333 | H15: =ROUND(E15*F15*1.84*(G15/60)*0.01,2) -> 0.9 | I15: 4.175 | J15: 1e-05 | K15: 99.833333 | L15: =I15*J15*1.84*(K15/60)*0.01 -> 1.2781994e-06 | M15: =H15-L15 -> 0.89999872 | N15: =N14+M15 -> 69.918436 | O15: =ROUND(M15/H15*100,2) -> 100 | P15: 0.30814516 | Q15: 71.33 | R15: 61.833333 | S15: =ROUND(P15*Q15*1.84*(R15/60)*0.01,2) -> 0.42 | T15: =T14+S15 -> 2.73 | U15: =IFERROR(ROUND(S15/M15 *100,2),0) -> 46.67
A16: 45982 | B16: 12 | C16: 0.25555556 | D16: =C16+D15 -> 3.0368056 | E16: 19.052679 | F16: 12.873929 | G16: 111.83333 | H16: =ROUND(E16*F16*1.84*(G16/60)*0.01,2) -> 8.41 | I16: 10.613839 | J16: 0.14285714 | K16: 111.83333 | L16: =I16*J16*1.84*(K16/60)*0.01 -> 0.052001074 | M16: =H16-L16 -> 8.3579989 | N16: =N15+M16 -> 78.276435 | O16: =ROUND(M16/H16*100,2) -> 99.38 | P16: 0.33141975 | Q16: 53.88 | R16: 53.833333 | S16: =ROUND(P16*Q16*1.84*(R16/60)*0.01,2) -> 0.29 | T16: =T15+S16 -> 3.02 | U16: =IFERROR(ROUND(S16/M16 *100,2),0) -> 3.47
A17: 45985 | B17: 13 | C17: 0.23125 | D17: =C17+D16 -> 3.2680556 | E17: 23.718868 | F17: 5.5124528 | G17: 52.833333 | H17: =ROUND(E17*F17*1.84*(G17/60)*0.01,2) -> 2.12 | I17: 12.641509 | J17: 0.11433962 | K17: 52.833333 | L17: =I17*J17*1.84*(K17/60)*0.01 -> 0.023419104 | M17: =H17-L17 -> 2.0965809 | N17: =N16+M17 -> 80.373015 | O17: =ROUND(M17/H17*100,2) -> 98.9 | P17: 0.674 | Q17: 40.69 | R17: 10 | S17: =ROUND(P17*Q17*1.84*(R17/60)*0.01,2) -> 0.08 | T17: =T16+S17 -> 3.1 | U17: =IFERROR(ROUND(S17/M17 *100,2),0) -> 3.82
... A42: 46043 | B42: 38 | C42: 0.25 | D42: =C42+D41 -> 8.8868056 | E42: 28.283333 | F42: 10.156667 | G42: 18 | H42: =ROUND(E42*F42*1.84*(G42/60)*0.01,2) -> 1.59 | I42: 13.333333 | J42: 0.072222222 | K42: 18 | L42: =I42*J42*1.84*(K42/60)*0.01 -> 0.0053155556 | M42: =H42-L42 -> 1.5846844 | N42: =N41+M42 -> 164.26488 | O42: =ROUND(M42/H42*100,2) -> 99.67 | P42: 1.47 | Q42: 100 | R42: 20 | S42: =ROUND(P42*Q42*1.84*(R42/60)*0.01,2) -> 0.9 | T42: =T41+S42 -> 20.35 | U42: =IFERROR(ROUND(S42/M42 *100,2),0) -> 56.79
A43: Total | C43: =AVERAGE(C5:C42) -> 0.2338633 | D43: =D42 -> 8.8868056 | E43: =AVERAGE(E5:E42) -> 21.219527 | H43: =AVERAGE(H5:H42) -> 4.3352632 | L43: =SUM(L5:L42) -> 0.47511936 | N43: =N42 -> 164.26488 | T43: =T42 -> 20.35
B50: Time | L50: Adsorp | Q50: Steam | Z50: Sorbent Aging
Z80: CO2 Capture&Recovery
Z107: CO2 Capture & Conc flue gas in

Sheet Run 3 Zeolite  
A1: Run 3 Zeolite
B3: Cycle | C3: Operating Hour | D3: Operating Hour Cumulative Run 4 Gen 1 | E3: CO₂In during adsorption | I3: CO₂Out during adsorption | M3: CO₂ Captured | P3: CO₂Regen during steaming
E4: Q (Nm³/h) | F4: C (vol%) | G4: T (min) | H4: CO₂ (kg) | I4: Q (Nm³/h) | J4: C (vol%) | K4: T (min) | L4: CO₂ (kg) | M4: CO₂ Captured Run 3 Zeolite | N4: CO₂ Captured Run 3 Zeolite Cumulative (Kg) | O4: % Captured | P4: Q (Nm³/h) | Q4: C (vol%) | R4: T (min) | S4: CO₂ (kg) | T4: CO2 Recovery Run 3 Zeolite Cumulative (Kg) | U4: % Recovery
A5: 46049 | B5: 1 | C5: 0.20486111 | D5: =C5 -> 0.20486111 | E5: 26.55 | F5: 11.807105 | G5: 38 | H5: =ROUND(E5*F5*1.84*(G5/60)*0.01,2) -> 3.65 | I5: 11.710526 | J5: 0.048421053 | K5: 38 | L5: =I5*J5*1.84*(K5/60)*0.01 -> 0.0066078596 | M5: =H5-L5 -> 3.6433921 | N5: =M5 -> 3.6433921 | O5: =ROUND(M5/H5*100,2) -> 99.82 | P5: 3.3 | Q5: 100 | R5: 5 | S5: =ROUND(P5*Q5*1.84*(R5/60)*0.01,2) -> 0.51 | T5: =S5 -> 0.51 | U5: =IFERROR(ROUND(S5/M5 *100,2),0) -> 14
A6: 46050 | B6: 2 | C6: 0.13402778 | D6: =D5+C6 -> 0.33888889 | E6: 16.666667 | F6: 12.885238 | G6: 21 | H6: =ROUND(E6*F6*1.84*(G6/60)*0.01,2) -> 1.38 | I6: 11.666667 | J6: 0.88952381 | K6: 21 | L6: =I6*J6*1.84*(K6/60)*0.01 -> 0.066832889 | M6: =H6-L6 -> 1.3131671 | N6: =N5+M6 -> 4.9565593 | O6: =ROUND(M6/H6*100,2) -> 95.16 | P6: 0.47111111 | Q6: 100 | R6: 45 | S6: =ROUND(P6*Q6*1.84*(R6/60)*0.01,2) -> 0.65 | T6: =T5+S6 -> 1.16 | U6: =IFERROR(ROUND(S6/M6 *100,2),0) -> 49.5
A7: 46051 | B7: 3 | C7: 0.18263889 | D7: =D6+C7 -> 0.52152778 | E7: 25.422222 | F7: 12.93 | G7: 9 | H7: =ROUND(E7*F7*1.84*(G7/60)*0.01,2) -> 0.91 | I7: 11.333333 | J7: 0.12222222 | K7: 9 | L7: =I7*J7*1.84*(K7/60)*0.01 -> 0.0038231111 | M7: =H7-L7 -> 0.90617689 | N7: =N6+M7 -> 5.8627361 | O7: =ROUND(M7/H7*100,2) -> 99.58 | P7: 0 | Q7: 0 | R7: 0 | S7: =ROUND(P7*Q7*1.84*(R7/60)*0.01,2) -> 0 | T7: =T6+S7 -> 1.16 | U7: =IFERROR(ROUND(S7/M7 *100,2),0) -> 0
A8: Total | D8: =D7 -> 0.52152778 | E8: =AVERAGE(E5:E7) -> 22.87963 | H8: =AVERAGE(H5:H7) -> 1.98 | L8: =SUM(L5:L7) -> 0.07726386 | M8: =SUM(M5:M7) -> 5.8627361 | N8: =N7 -> 5.8627361 | O8: =AVERAGE(O5:O7) -> 98.186667 | S8: =SUM(S5:S7) -> 1.16
B12: Time | N12: Adsorp | V12: Steam | AH12: Sorbent Aging
AH42: CO2 Capture&Recovery
AH69: CO2 Capture & Conc flue gas in

Sheet Run 4 Gen 1 + Zeolite 
A1: Run 4 Gen 1 + Zeolite
B3: Cycle | C3: Operating Hour | D3: Operating Hour Cumulative Run 4 Gen 1 | E3: CO₂In during adsorption | I3: CO₂Out during adsorption | M3: CO₂ Captured | P3: CO₂Regen during steaming
E4: Q (Nm³/h) | F4: C (vol%) | G4: T (min) | H4: CO₂ (kg) | I4: Q (Nm³/h) | J4: C (vol%) | K4: T (min) | L4: CO₂ (kg) | M4: CO₂ Captured Run 4 Gen 1 + Zeolite | N4: CO₂ Captured Run 4 Gen 1 + Zeolite Cumulative (Kg) | O4: % Captured | P4: Q (Nm³/h) | Q4: C (vol%) | R4: T (min) | S4: CO₂ (kg) | T4: CO2 Recovery Run 4 Gen 1 + Zeolite Cumulative (Kg) | U4: % Recovery
A5: 46055 | B5: 1 | C5: 0.23541667 | D5: =C5 -> 0.23541667 | E5: 20.938182 | F5: 13 | G5: 110 | H5: =ROUND(E5*F5*1.84*(G5/60)*0.01,2) -> 9.18 | I5: 11.563636 | J5: 0.012636364 | K5: 110 | L5: =I5*J5*1.84*(K5/60)*0.01 -> 0.0049291927 | M5: =H5-L5 -> 9.1750708 | N5: =M5 -> 9.1750708 | O5: =ROUND(M5/H5*100,2) -> 99.95 | P5: 4.3454545 | Q5: 99.320909 | R5: 11 | S5: =ROUND(P5*Q5*1.84*(R5/60)*0.01,2) -> 1.46 | T5: =S5 -> 1.46 | U5: =IFERROR(ROUND(S5/M5 *100,2),0) -> 15.91
A6: 46056 | B6: 2 | C6: 0.17291667 | D6: =D5+C6 -> 0.40833333 | E6: 15.269231 | F6: 12.507885 | G6: 52 | H6: =ROUND(E6*F6*1.84*(G6/60)*0.01,2) -> 3.05 | I6: 15 | J6: 0.030961538 | K6: 52 | L6: =I6*J6*1.84*(K6/60)*0.01 -> 0.007406 | M6: =H6-L6 -> 3.042594 | N6: =N5+M6 -> 12.217665 | O6: =ROUND(M6/H6*100,2) -> 99.76 | P6: - | Q6: - | R6: - | S6: - | T6: - | U6: -
A7: 46057 | B7: 3 | C7: 0.21944444 | D7: =D6+C7 -> 0.62777778 | E7: 15.4 | F7: 13.014808 | G7: 52 | H7: =ROUND(E7*F7*1.84*(G7/60)*0.01,2) -> 3.2 | I7: 13.923077 | J7: 0.038653846 | K7: 52 | L7: =I7*J7*1.84*(K7/60)*0.01 -> 0.0085821846 | M7: =H7-L7 -> 3.1914178 | N7: =N6+M7 -> 15.409083 | O7: =ROUND(M7/H7*100,2) -> 99.73 | P7: 5.7857143 | Q7: 99.764286 | R7: 7 | S7: =ROUND(P7*Q7*1.84*(R7/60)*0.01,2) -> 1.24 | T7: =T5+S7 -> 2.7 | U7: =IFERROR(ROUND(S7/M7 *100,2),0) -> 38.85
A8: 46058 | B8: 4 | C8: 0.19861111 | D8: =D7+C8 -> 0.82638889 | E8: 23.320313 | F8: 12.901094 | G8: 64 | H8: =ROUND(E8*F8*1.84*(G8/60)*0.01,2) -> 5.9 | I8: 13 | J8: 0.0403125 | K8: 64 | L8: =I8*J8*1.84*(K8/60)*0.01 -> 0.0102856 | M8: =H8-L8 -> 5.8897144 | N8: =N7+M8 -> 21.298797 | O8: =ROUND(M8/H8*100,2) -> 99.83 | P8: 4.125 | Q8: 97.515 | R8: 12 | S8: =ROUND(P8*Q8*1.84*(R8/60)*0.01,2) -> 1.48 | T8: =T7+S8 -> 4.18 | U8: =IFERROR(ROUND(S8/M8 *100,2),0) -> 25.13
A9: 46059 | B9: 5 | C9: 0.27430556 | D9: =D8+C9 -> 1.1006944 | E9: 27.169231 | F9: 12.39 | G9: 52 | H9: =ROUND(E9*F9*1.84*(G9/60)*0.01,2) -> 5.37 | I9: 13.807692 | J9: 0.025576923 | K9: 52 | L9: =I9*J9*1.84*(K9/60)*0.01 -> 0.0056316974 | M9: =H9-L9 -> 5.3643683 | N9: =N8+M9 -> 26.663165 | O9: =ROUND(M9/H9*100,2) -> 99.9 | P9: 2.6466667 | Q9: 99.460667 | R9: 15 | S9: =ROUND(P9*Q9*1.84*(R9/60)*0.01,2) -> 1.21 | T9: =T8+S9 -> 5.39 | U9: =IFERROR(ROUND(S9/M9 *100,2),0) -> 22.56
A10: 46062 | B10: 6 | C10: 0.25625 | D10: =D9+C10 -> 1.3569444 | E10: 22.31746 | F10: 12.488254 | G10: 63 | H10: =ROUND(E10*F10*1.84*(G10/60)*0.01,2) -> 5.38 | I10: 13.47619 | J10: 0.027619048 | K10: 63 | L10: =I10*J10*1.84*(K10/60)*0.01 -> 0.0071908952 | M10: =H10-L10 -> 5.3728091 | N10: =N9+M10 -> 32.035974 | O10: =ROUND(M10/H10*100,2) -> 99.87 | P10: 2.5466667 | Q10: 56.583389 | R10: 30 | S10: =ROUND(P10*Q10*1.84*(R10/60)*0.01,2) -> 1.33 | T10: =T9+S10 -> 6.72 | U10: =IFERROR(ROUND(S10/M10 *100,2),0) -> 24.75
A11: 46063 | B11: 7 | C11: 0.15 | D11: =D10+C11 -> 1.5069444 | E11: 24.038983 | F11: 12.311356 | G11: 59 | H11: =ROUND(E11*F11*1.84*(G11/60)*0.01,2) -> 5.35 | I11: 13.677966 | J11: 0.021864407 | K11: 59 | L11: =I11*J11*1.84*(K11/60)*0.01 -> 0.0054110034 | M11: =H11-L11 -> 5.344589 | N11: =N10+M11 -> 37.380563 | O11: =ROUND(M11/H11*100,2) -> 99.9 | P11: 1.8076923 | Q11: 79.864006 | R11: 52 | S11: =ROUND(P11*Q11*1.84*(R11/60)*0.01,2) -> 2.3 | T11: =T10+S11 -> 9.02 | U11: =IFERROR(ROUND(S11/M11 *100,2),0) -> 43.03
A12: 46064 | B12: 8 | C12: 0.26805556 | D12: =D11+C12 -> 1.775 | E12: 23.098529 | F12: 12.578529 | G12: 68 | H12: =ROUND(E12*F12*1.84*(G12/60)*0.01,2) -> 6.06 | I12: 11.882353 | J12: 0.039705882 | K12: 68 | L12: =I12*J12*1.84*(K12/60)*0.01 -> 0.0098385882 | M12: =H12-L12 -> 6.0501614 | N12: =N11+M12 -> 43.430725 | O12: =ROUND(M12/H12*100,2) -> 99.84 | P12: 0.66730769 | Q12: 55.612532 | R12: 104 | S12: =ROUND(P12*Q12*1.84*(R12/60)*0.01,2) -> 1.18 | T12: =T11+S12 -> 10.2 | U12: =IFERROR(ROUND(S12/M12 *100,2),0) -> 19.5
A13: 46065 | B13: 9 | C13: 0.32430556 | D13: =D12+C13 -> 2.0993056 | E13: 15.622449 | F13: 14.55 | G13: 49 | H13: =ROUND(E13*F13*1.84*(G13/60)*0.01,2) -> 3.42 | I13: 17.489796 | J13: 0.02755102 | K13: 49 | L13: =I13*J13*1.84*(K13/60)*0.01 -> 0.0072407755 | M13: =H13-L13 -> 3.4127592 | N13: =N12+M13 -> 46.843484 | O13: =ROUND(M13/H13*100,2) -> 99.79 | P13: 1.5452381 | Q13: 47.983016 | R13: 42 | S13: =ROUND(P13*Q13*1.84*(R13/60)*0.01,2) -> 0.95 | T13: =T12+S13 -> 11.15 | U13: =IFERROR(ROUND(S13/M13 *100,2),0) -> 27.84
A14: 46066 | B14: 10 | C14: 0.22777778 | D14: =D13+C14 -> 2.3270833 | E14: 22.473913 | F14: 11.725435 | G14: 46 | H14: =ROUND(E14*F14*1.84*(G14/60)*0.01,2) -> 3.72 | I14: 14 | J14: 0.022826087 | K14: 46 | L14: =I14*J14*1.84*(K14/60)*0.01 -> 0.004508 | M14: =H14-L14 -> 3.715492 | N14: =N13+M14 -> 50.558976 | O14: =ROUND(M14/H14*100,2) -> 99.88 | P14: 1.2090909 | Q14: 27.986061 | R14: 44 | S14: =ROUND(P14*Q14*1.84*(R14/60)*0.01,2) -> 0.46 | T14: =T13+S14 -> 11.61 | U14: =IFERROR(ROUND(S14/M14 *100,2),0) -> 12.38
A15: 46069 | B15: 11 | C15: 0.26319444 | D15: =D14+C15 -> 2.5902778 | E15: 21.26087 | F15: 11.517101 | G15: 69 | H15: =ROUND(E15*F15*1.84*(G15/60)*0.01,2) -> 5.18 | I15: 12.478261 | J15: 0.052608696 | K15: 69 | L15: =I15*J15*1.84*(K15/60)*0.01 -> 0.0138908 | M15: =H15-L15 -> 5.1661092 | N15: =N14+M15 -> 55.725085 | O15: =ROUND(M15/H15*100,2) -> 99.73 | P15: 2.0003257 | Q15: 33.547752 | R15: 51.166667 | S15: =ROUND(P15*Q15*1.84*(R15/60)*0.01,2) -> 1.05 | T15: =T14+S15 -> 12.66 | U15: =IFERROR(ROUND(S15/M15 *100,2),0) -> 20.32
A16: 46070 | B16: 12 | C16: 0.24722222 | D16: =D15+C16 -> 2.8375 | E16: 22.272464 | F16: 11.372754 | G16: 69 | H16: =ROUND(E16*F16*1.84*(G16/60)*0.01,2) -> 5.36 | I16: 12.478261 | J16: 0.052608696 | K16: 69 | L16: =I16*J16*1.84*(K16/60)*0.01 -> 0.0138908 | M16: =H16-L16 -> 5.3461092 | N16: =N15+M16 -> 61.071194 | O16: =ROUND(M16/H16*100,2) -> 99.74 | P16: 2.1680851 | Q16: 57.502979 | R16: 47 | S16: =ROUND(P16*Q16*1.84*(R16/60)*0.01,2) -> 1.8 | T16: =T15+S16 -> 14.46 | U16: =IFERROR(ROUND(S16/M16 *100,2),0) -> 33.67
A17: 46071 | B17: 13 | C17: 0.23472222 | D17: =D16+C17 -> 3.0722222 | E17: 21.814286 | F17: 11.474921 | G17: 63 | H17: =ROUND(E17*F17*1.84*(G17/60)*0.01,2) -> 4.84 | I17: 12.952381 | J17: 0.028412698 | K17: 63 | L17: =I17*J17*1.84*(K17/60)*0.01 -> 0.0071099937 | M17: =H17-L17 -> 4.83289 | N17: =N16+M17 -> 65.904084 | O17: =ROUND(M17/H17*100,2) -> 99.85 | P17: 2.296 | Q17: 31.674067 | R17: 25 | S17: =ROUND(P17*Q17*1.84*(R17/60)*0.01,2) -> 0.56 | T17: =T16+S17 -> 15.02 | U17: =IFERROR(ROUND(S17/M17 *100,2),0) -> 11.59
A18: Total | D18: =D17 -> 3.0722222 | E18: =AVERAGE(E5:E17) -> 21.153532 | H18: =AVERAGE(H5:H17) -> 5.0776923 | L18: =SUM(L5:L17) -> 0.10591553 | M18: =SUM(M5:M17) -> 65.904084 | N18: =N17 -> 65.904084 | O18: =AVERAGE(O5:O17) -> 99.828462 | S18: =SUM(S5:S17) -> 15.02
B24: Time | L24: Adsorp | P24: Steam | AB24: Sorbent Aging
AB54: CO2 Capture&Recovery
AB82: CO2 Capture & Conc flue gas in

Sheet Run 5 Gen 1+Gen 2.2+ Zeolite
A1: Run 5 Gen 1+Gen 2.2+ Zeolite
B3: Cycle | C3: Operating Hour | D3: Operating Hour Cumulative Run 5 Gen 1+Gen 2.2+ Zeolite | E3: CO₂In during adsorption | I3: CO₂Out during adsorption | M3: CO₂ Captured | P3: CO₂Regen during steaming
E4: Q (Nm³/h) | F4: C (vol%) | G4: T (min) | H4: CO₂ (kg) | I4: Q (Nm³/h) | J4: C (vol%) | K4: T (min) | L4: CO₂ (kg) | M4: CO₂ Captured Run 5 Gen 1+Gen 2.2+ Zeolite (Kg) | N4: CO₂ Captured Run 5 Gen 1+Gen 2.2+ Zeolite Cumulative (Kg) | O4: % Captured | P4: Q (Nm³/h) | Q4: C (vol%) | R4: T (min) | S4: CO₂ (kg) | T4: CO2 Recovery Run 5 Gen 1+Gen 2.2+ Zeolite Cumulative (Kg) | U4: % Recovery
A5: 46076 | B5: 1 | C5: 0.22916667 | D5: =C5 -> 0.22916667 | E5: 24.9 | F5: 11.772439 | G5: 41 | H5: =ROUND(E5*F5*1.84*(G5/60)*0.01,2) -> 3.69 | I5: 14.512195 | J5: 0.071707317 | K5: 41 | L5: =I5*J5*1.84*(K5/60)*0.01 -> 0.013084195 | M5: =H5-L5 -> 3.6769158 | N5: =M5 -> 3.6769158 | O5: =ROUND(M5/H5*100,2) -> 99.65 | P5: 2.4837209 | Q5: 22.486783 | R5: 43 | S5: 1.1 | T5: =S5 -> 1.1 | U5: =IFERROR(ROUND(S5/M5 *100,2),0) -> 29.92
A6: 46077 | B6: 2 | C6: 0.27083333 | D6: =D5+C6 -> 0.5 | E6: 20.498077 | F6: 11.000962 | G6: 52 | H6: =ROUND(E6*F6*1.84*(G6/60)*0.01,2) -> 3.6 | I6: 14.384615 | J6: 0.078269231 | K6: 52 | L6: =I6*J6*1.84*(K6/60)*0.01 -> 0.017953918 | M6: =H6-L6 -> 3.5820461 | N6: =N5+M6 -> 7.2589619 | O6: =ROUND(M6/H6*100,2) -> 99.5 | P6: 0.96666667 | Q6: 4.8850585 | R6: 57 | S6: 0.35 | T6: =T5+S6 -> 1.45 | U6: 4.77
A7: 46078 | B7: 3 | C7: 0.29097222 | D7: =D6+C7 -> 0.79097222 | E7: 17.328571 | F7: 10.969048 | G7: 42 | H7: =ROUND(E7*F7*1.84*(G7/60)*0.01,2) -> 2.45 | I7: 15.071429 | J7: 0.025238095 | K7: 42 | L7: =I7*J7*1.84*(K7/60)*0.01 -> 0.004899219 | M7: =H7-L7 -> 2.4451008 | N7: =N6+M7 -> 9.7040627 | O7: =ROUND(M7/H7*100,2) -> 99.8 | P7: 1.5177866 | Q7: 17.940514 | R7: 42.166667 | S7: 0.6 | T7: =T6+S7 -> 2.05 | U7: =IFERROR(ROUND(S7/M7 *100,2),0) -> 24.54
A8: 46079 | B8: 4 | C8: 0.36527778 | D8: =D7+C8 -> 1.15625 | E8: 23.438095 | F8: 19.261905 | G8: 42 | H8: =ROUND(E8*F8*1.84*(G8/60)*0.01,2) -> 5.81 | I8: 15.714286 | J8: 0.023809524 | K8: 42 | L8: =I8*J8*1.84*(K8/60)*0.01 -> 0.0048190476 | M8: =H8-L8 -> 5.805181 | N8: =N7+M8 -> 15.509244 | O8: =ROUND(M8/H8*100,2) -> 99.92 | P8: 1.1038462 | Q8: 25.206538 | R8: 52 | S8: 1.32 | T8: =T7+S8 -> 3.37 | U8: =IFERROR(ROUND(S8/M8 *100,2),0) -> 22.74
A9: 46080 | B9: 5 | C9: 0.31666667 | D9: =D8+C9 -> 1.4729167 | E9: 13.688372 | F9: 11.988837 | G9: 43 | H9: 2.01 | I9: 12.186047 | J9: 0.05627907 | K9: 43 | L9: =I9*J9*1.84*(K9/60)*0.01 -> 0.0090436713 | M9: =H9-L9 -> 2.0009563 | N9: =N8+M9 -> 17.5102 | O9: =ROUND(M9/H9*100,2) -> 99.55 | P9: 1.220339 | Q9: 15.700734 | R9: 59 | S9: 0.6 | T9: =T8+S9 -> 3.97 | U9: =IFERROR(ROUND(S9/M9 *100,2),0) -> 29.99
A10: 46083 | B10: 6 | C10: 0.30694444 | D10: =D9+C10 -> 1.7798611 | E10: 23.948276 | F10: 13.651724 | G10: 29 | H10: =ROUND(E10*F10*1.84*(G10/60)*0.01,2) -> 2.91 | I10: 12.275862 | J10: 0.092068966 | K10: 29 | L10: =I10*J10*1.84*(K10/60)*0.01 -> 0.010051476 | M10: =H10-L10 -> 2.8999485 | N10: =N9+M10 -> 20.410148 | O10: =ROUND(M10/H10*100,2) -> 99.65 | P10: 0.98163934 | Q10: 9.1590492 | R10: 50.833333 | S10: 0.7 | T10: =T9+S10 -> 4.67 | U10: =IFERROR(ROUND(S10/M10 *100,2),0) -> 24.14
A11: 46085 | B11: 7 | C11: 0.31597222 | D11: =D10+C11 -> 2.0958333 | E11: 17.85 | F11: 14.335 | G11: 22 | H11: =ROUND(E11*F11*1.84*(G11/60)*0.01,2) -> 1.73 | I11: 15.454545 | J11: 0.10454545 | K11: 22 | L11: =I11*J11*1.84*(K11/60)*0.01 -> 0.010900606 | M11: =H11-L11 -> 1.7190994 | N11: =N10+M11 -> 22.129248 | O11: =ROUND(M11/H11*100,2) -> 99.37 | P11: 2.4016667 | Q11: 54.160944 | R11: 60 | S11: 2.5 | T11: =T10+S11 -> 7.17 | U11: =IFERROR(ROUND(S11/M11 *100,2),0) -> 145.42
A12: 46086 | B12: 8 | C12: 0.27847222 | D12: =D11+C12 -> 2.3743056 | E12: 22.911538 | F12: 14.148077 | G12: 26 | H12: =ROUND(E12*F12*1.84*(G12/60)*0.01,2) -> 2.58 | I12: 14.538462 | J12: 0.105 | K12: 26 | L12: =I12*J12*1.84*(K12/60)*0.01 -> 0.0121716 | M12: =H12-L12 -> 2.5678284 | N12: =N11+M12 -> 24.697076 | O12: =ROUND(M12/H12*100,2) -> 99.53 | P12: 1 | Q12: 7.2979085 | R12: 51 | S12: 0.5 | T12: =T11+S12 -> 7.67 | U12: =IFERROR(ROUND(S12/M12 *100,2),0) -> 19.47
A13: 46087 | B13: 9 | C13: 0.27291667 | D13: =D12+C13 -> 2.6472222 | E13: 15.795833 | F13: 13.43375 | G13: 24 | H13: =ROUND(E13*F13*1.84*(G13/60)*0.01,2) -> 1.56 | I13: 15 | J13: 0.1275 | K13: 24 | L13: =I13*J13*1.84*(K13/60)*0.01 -> 0.014076 | M13: =H13-L13 -> 1.545924 | N13: =N12+M13 -> 26.243 | O13: =ROUND(M13/H13*100,2) -> 99.1 | P13: 0.90465116 | Q13: 2.6212791 | R13: 43 | S13: 0.04 | T13: =T12+S13 -> 7.71 | U13: =IFERROR(ROUND(S13/M13 *100,2),0) -> 2.59
A14: 46090 | B14: 10 | C14: 0.32638889 | D14: =D13+C14 -> 2.9736111 | E14: 24.5 | F14: 14.001304 | G14: 23 | H14: =ROUND(E14*F14*1.84*(G14/60)*0.01,2) -> 2.42 | I14: 18 | J14: 0.15695652 | K14: 23 | L14: =I14*J14*1.84*(K14/60)*0.01 -> 0.0199272 | M14: =H14-L14 -> 2.4000728 | N14: =N13+M14 -> 28.643073 | O14: =ROUND(M14/H14*100,2) -> 99.18 | P14: 0.54835165 | Q14: 41.742308 | R14: 91 | S14: 0.83 | T14: =T13+S14 -> 8.54 | U14: =IFERROR(ROUND(S14/M14 *100,2),0) -> 34.58
A15: 46091 | B15: 11 | C15: 0.28541667 | D15: =D14+C15 -> 3.2590278 | E15: 24.195 | F15: 13.953 | G15: 20 | H15: =ROUND(E15*F15*1.84*(G15/60)*0.01,2) -> 2.07 | I15: 18 | J15: 0.154 | K15: 20 | L15: =I15*J15*1.84*(K15/60)*0.01 -> 0.0170016 | M15: =H15-L15 -> 2.0529984 | N15: =N14+M15 -> 30.696071 | O15: =ROUND(M15/H15*100,2) -> 99.18 | P15: 2.0212121 | Q15: 48.60904 | R15: 33 | S15: 0.85 | T15: =T14+S15 -> 9.39 | U15: =IFERROR(ROUND(S15/M15 *100,2),0) -> 41.4
A16: 46092 | B16: 12 | C16: 0.30763889 | D16: =D15+C16 -> 3.5666667 | E16: 25.264706 | F16: 14 | G16: 17 | H16: =ROUND(E16*F16*1.84*(G16/60)*0.01,2) -> 1.84 | I16: 16 | J16: 0.12588235 | K16: 17 | L16: =I16*J16*1.84*(K16/60)*0.01 -> 0.010500267 | M16: =H16-L16 -> 1.8294997 | N16: =N15+M16 -> 32.525571 | O16: =ROUND(M16/H16*100,2) -> 99.43 | P16: 2.2874773 | Q16: 42.147042 | R16: 91.833333 | S16: 2.81 | T16: =T15+S16 -> 12.2 | U16: =IFERROR(ROUND(S16/M16 *100,2),0) -> 153.59
A17: 46093 | B17: 13 | C17: 0.27013889 | D17: =D16+C17 -> 3.8368056 | E17: 22.906667 | F17: 14.093333 | G17: 15 | H17: =ROUND(E17*F17*1.84*(G17/60)*0.01,2) -> 1.49 | I17: 18 | J17: 0.144 | K17: 15 | L17: =I17*J17*1.84*(K17/60)*0.01 -> 0.0119232 | M17: =H17-L17 -> 1.4780768 | N17: =N16+M17 -> 34.003648 | O17: =ROUND(M17/H17*100,2) -> 99.2 | P17: 2.3217391 | Q17: 65.015507 | R17: 46 | S17: 2 | T17: =T16+S17 -> 14.2 | U17: =IFERROR(ROUND(S17/M17 *100,2),0) -> 135.31
A18: 46094 | B18: 14 | C18: 0.33055556 | D18: =D17+C18 -> 4.1673611 | E18: 24.669565 | F18: 11.583913 | G18: 23 | H18: =ROUND(E18*F18*1.84*(G18/60)*0.01,2) -> 2.02 | I18: 16 | J18: 0.16304348 | K18: 23 | L18: =I18*J18*1.84*(K18/60)*0.01 -> 0.0184 | M18: =H18-L18 -> 2.0016 | N18: =N17+M18 -> 36.005248 | O18: =ROUND(M18/H18*100,2) -> 99.09 | P18: 2.1764706 | Q18: 49.71902 | R18: 119 | S18: 3.98 | T18: =T17+S18 -> 18.18 | U18: =IFERROR(ROUND(S18/M18 *100,2),0) -> 198.84
A19: 46097 | B19: 15 | C19: 0.28125 | D19: =D18+C19 -> 4.4486111 | E19: 13.361538 | F19: 13.692308 | G19: 13 | H19: =ROUND(E19*F19*1.84*(G19/60)*0.01,2) -> 0.73 | I19: 18 | J19: 0.14846154 | K19: 13 | L19: =I19*J19*1.84*(K19/60)*0.01 -> 0.0106536 | M19: =H19-L19 -> 0.7193464 | N19: =N18+M19 -> 36.724594 | O19: =ROUND(M19/H19*100,2) -> 98.54 | P19: 1.7214286 | Q19: 5.4480952 | R19: 28 | S19: 0.15 | T19: =T18+S19 -> 18.33 | U19: =IFERROR(ROUND(S19/M19 *100,2),0) -> 20.85
A20: 46098 | B20: 16 | C20: 0.25972222 | D20: =D19+C20 -> 4.7083333 | E20: 17.426316 | F20: 13.8 | G20: 19 | H20: =ROUND(E20*F20*1.84*(G20/60)*0.01,2) -> 1.4 | I20: 16 | J20: 0.11947368 | K20: 19 | L20: =I20*J20*1.84*(K20/60)*0.01 -> 0.011138133 | M20: =H20-L20 -> 1.3888619 | N20: =N19+M20 -> 38.113456 | O20: =ROUND(M20/H20*100,2) -> 99.2 | P20: 1.4 | Q20: 3.9227419 | R20: 31 | S20: 0.13 | T20: =T19+S20 -> 18.46 | U20: =IFERROR(ROUND(S20/M20 *100,2),0) -> 9.36
A21: 46099 | B21: 17 | C21: 0.22638889 | D21: 8.5284722 | E21: 14.185714 | F21: 13.878571 | G21: 14 | H21: =ROUND(E21*F21*1.84*(G21/60)*0.01,2) -> 0.85 | I21: 16 | J21: 0.2 | K21: 14 | L21: =I21*J21*1.84*(K21/60)*0.01 -> 0.013738667 | M21: =H21-L21 -> 0.83626133 | N21: =N20+M21 -> 38.949718 | O21: =ROUND(M21/H21*100,2) -> 98.38 | P21: 2.3923077 | Q21: 8.2163462 | R21: 26 | S21: 0.19 | T21: =T20+S21 -> 18.65 | U21: =IFERROR(ROUND(S21/M21 *100,2),0) -> 22.72
A22: 46100 | B22: 18 | C22: 0.30347222 | D22: =D21+C22 -> 8.8319444 | E22: 13.866667 | F22: 12.1 | G22: 18 | H22: =ROUND(E22*F22*1.84*(G22/60)*0.01,2) -> 0.93 | I22: 14 | J22: 0.064814815 | K22: 18 | L22: =I22*J22*1.84*(K22/60)*0.01 -> 0.0050088889 | M22: =H22-L22 -> 0.92499111 | N22: =N21+M22 -> 39.874709 | O22: =ROUND(M22/H22*100,2) -> 99.46 | P22: 1.26875 | Q22: 15.78224 | R22: 32 | S22: 0.01 | T22: =T21+S22 -> 18.66 | U22: =IFERROR(ROUND(S22/M22 *100,2),0) -> 1.08
A23: Total | D23: =D22 -> 8.8319444 | E23: =AVERAGE(E5:E22) -> 20.04083 | H23: =AVERAGE(H5:H22) -> 2.2272222 | L23: =SUM(L5:L22) -> 0.21529129 | M23: =SUM(M5:M22) -> 39.874709 | N23: =N22 -> 39.874709 | O23: =AVERAGE(O5:O22) -> 99.318333 | T23: =T22 -> 18.66
B27: Time | L27: Adsorp | P27: Steam | AB27: Sorbent Aging
AB59: CO2 Capture&Recovery
AB86: CO2 Capture & Conc flue gas in

Sheet Run 3, 4, and 5
A1: Run 3,4, and 5
B3: Cycle | C3: Operating Hour | D3: Operating Hour Cumulative Run 3,4, and 5 | E3: CO₂In during adsorption | I3: CO₂Out during adsorption | M3: CO₂ Captured | P3: CO₂Regen during steaming
E4: Q (Nm³/h) | F4: C (vol%) | G4: T (min) | H4: CO₂ (kg) | I4: Q (Nm³/h) | J4: C (vol%) | K4: T (min) | L4: CO₂ (kg) | M4: CO₂ Captured Run 3,4, and 5 (Kg) | N4: CO₂ Captured Run 3,4, and 5 Cumulative (Kg) | O4: % Captured | P4: Q (Nm³/h) | Q4: C (vol%) | R4: T (min) | S4: CO₂ (kg) | T4: CO2 Recovery Run 3,4, and 5 Cumulative (Kg) | U4: % Recovery
A5: 46049 | B5: 1 | C5: 0.20486111 | D5: =C5 -> 0.20486111 | E5: 26.55 | F5: 11.807105 | G5: 38 | H5: =ROUND(E5*F5*1.84*(G5/60)*0.01,2) -> 3.65 | I5: 11.710526 | J5: 0.048421053 | K5: 38 | L5: =I5*J5*1.84*(K5/60)*0.01 -> 0.0066078596 | M5: =H5-L5 -> 3.6433921 | N5: =M5 -> 3.6433921 | O5: =ROUND(M5/H5*100,2) -> 99.82 | P5: 3.3 | Q5: 100 | R5: 5 | S5: 0.51 | T5: =S5 -> 0.51 | U5: =IFERROR(ROUND(S5/M5 *100,2),0) -> 14
A6: 46050 | B6: 2 | C6: 0.13402778 | D6: =D5+C6 -> 0.33888889 | E6: 16.666667 | F6: 12.885238 | G6: 21 | H6: =ROUND(E6*F6*1.84*(G6/60)*0.01,2) -> 1.38 | I6: 11.666667 | J6: 0.88952381 | K6: 21 | L6: =I6*J6*1.84*(K6/60)*0.01 -> 0.066832889 | M6: =H6-L6 -> 1.3131671 | N6: =N5+M6 -> 4.9565593 | O6: =ROUND(M6/H6*100,2) -> 95.16 | P6: 0.47111111 | Q6: 100 | R6: 45 | S6: 0.65 | T6: =T5+S6 -> 1.16 | U6: 4.77
A7: 46051 | B7: 3 | C7: 0.18263889 | D7: =D6+C7 -> 0.52152778 | E7: 25.422222 | F7: 12.93 | G7: 9 | H7: =ROUND(E7*F7*1.84*(G7/60)*0.01,2) -> 0.91 | I7: 11.333333 | J7: 0.12222222 | K7: 9 | L7: =I7*J7*1.84*(K7/60)*0.01 -> 0.0038231111 | M7: =H7-L7 -> 0.90617689 | N7: =N6+M7 -> 5.8627361 | O7: =ROUND(M7/H7*100,2) -> 99.58 | P7: 0 | Q7: 0 | R7: 0 | S7: 0 | T7: =T6+S7 -> 1.16 | U7: =IFERROR(ROUND(S7/M7 *100,2),0) -> 0
A8: 46055 | B8: 4 | C8: 0.23541667 | D8: =D7+C8 -> 0.75694444 | E8: 20.938182 | F8: 13 | G8: 110 | H8: =ROUND(E8*F8*1.84*(G8/60)*0.01,2) -> 9.18 | I8: 11.563636 | J8: 0.012636364 | K8: 110 | L8: =I8*J8*1.84*(K8/60)*0.01 -> 0.0049291927 | M8: =H8-L8 -> 9.1750708 | N8: =N7+M8 -> 15.037807 | O8: =ROUND(M8/H8*100,2) -> 99.95 | P8: 4.3454545 | Q8: 99.320909 | R8: 11 | S8: 1.46 | T8: =T7+S8 -> 2.62 | U8: =IFERROR(ROUND(S8/M8 *100,2),0) -> 15.91
A9: 46056 | B9: 5 | C9: 0.17291667 | D9: =D8+C9 -> 0.92986111 | E9: 15.269231 | F9: 12.507885 | G9: 52 | H9: 2.01 | I9: 15 | J9: 0.030961538 | K9: 52 | L9: =I9*J9*1.84*(K9/60)*0.01 -> 0.007406 | M9: =H9-L9 -> 2.002594 | N9: =N8+M9 -> 17.040401 | O9: =ROUND(M9/H9*100,2) -> 99.63 | P9: - | Q9: - | R9: - | S9: 0 | T9: =T8+S9 -> 2.62 | U9: =IFERROR(ROUND(S9/M9 *100,2),0) -> 0
